Workbook

Sheet Données sources
A1: ADVANS CI — Données sources transcrites des documents transmis
A3: ⚠ Toutes les valeurs de cette feuille sont des INPUTS (bleu) transcrits tels quels des captures d'écran fournies. Elles proviennent de DEUX documents distincts (voir origine indiquée pour chaque table).
A5: TABLE A — Modalités de remboursement proposées (document 'ancienne demande', p.21)
A6: En MXOF | B6: 2025 | C6: 2026 | D6: 2027 | E6: 2028 | F6: 2029
A7: Coût du risque | B7: 3776 | C7: 2539 | D7: 2539 | E7: 2539 | F7: 2539
A8: RN | B8: 1570 | C8: 1570 | D8: 1570 | E8: 1570 | F8: 1570
A9: Cash-flow | B9: =B7+B8 -> 5346 | C9: =C7+C8 -> 4109 | D9: =D7+D8 -> 4109 | E9: =E7+E8 -> 4109 | F9: =F7+F8 -> 4109
A10: Amortissement Nouvelle dette SGCI | C10: 152 | D10: 321 | E10: 344 | F10: 181
A11: Amortissement des précédentes dettes | B11: 3301 | C11: 3268 | D11: 2370 | E11: 3674 | F11: 2585
A12: Cash-flow net | B12: =B9-(B10+B11) -> 2045 | C12: =C9-(C10+C11) -> 689 | D12: =D9-(D10+D11) -> 1418 | E12: =E9-(E10+E11) -> 91 | F12: =F9-(F10+F11) -> 1343
A13: Couverture de la dette (donnée telle quelle) | B13: =B9/(B10+B11) -> 1.6195092 | C13: =C9/(C10+C11) -> 1.201462 | D13: =D9/(D10+D11) -> 1.5269417 | E13: =E9/(E10+E11) -> 1.0226481 | F13: =F9/(F10+F11) -> 1.4855387
A14: Contrôle — Cash-flow recalculé (Coût du risque + RN) | B14: =B7+B8 -> 5346 | C14: =C7+C8 -> 4109 | D14: =D7+D8 -> 4109 | E14: =E7+E8 -> 4109 | F14: =F7+F8 -> 4109
A15: Écart vs Cash-flow tel que fourni par le client (doit être 0) | B15: =B14-B9 -> 0 | C15: =C14-C9 -> 0 | D15: =D14-D9 -> 0
A17: ⚠ POINT MÉTHODOLOGIQUE MAJEUR : le document source intitule lui-même ce tableau « récapitulatif des remboursements EN CAPITAL » — les INTÉRÊTS ne sont PAS inclus dans « Amortissement de dettes » ni dans le ratio « Couverture de la dette » ci-dessus (1,10x/1,05x/1,82x/7,89x). Un vrai ratio de couverture du service de la dette (DSCR) doit intégrer capital + intérêts. Les ratios affichés surestiment donc la couverture réelle. Le calendrier des intérêts par ligne n'est pas disponible dans les documents transmis — à obtenir impérativement du chargé d'affaires avant de valider la soutenabilité du dossier.
A18: Note : ce tableau date d'une précédente demande de CMT. Le RN 2024 projeté ici (2 773 281) est ~40% supérieur au RN 2024 réellement audité (1 657 371) — fiabilité à prendre avec prudence.
A21: TABLE B — Récapitulatif des remboursements en capital par bailleur (document 'ancienne demande', p.21)
A22: En KXOF | B22: 2025 | C22: 2026 | D22: 2027
A23: BACI | B23: 532449
A24: NSIA BANQUE | B24: 457662
A25: BLUEOCHARD | B25: 819946 | C25: 819946
A26: SANAD | B26: 787148 | C26: 787148
A27: BICICI | B27: 532512
A28: BIO 1 | B28: 218652 | C28: 109326
A29: BIO 2 | B29: 153056 | C29: 76528
A30: BIO 3 | B30: 284248 | C30: 142124
A31: Nouveau Crédit SG | B31: 818771 | C31: 838043 | D31: 641452
A32: TOTAL | B32: =SUM(B23:B31) -> 4604444 | C32: =SUM(C23:C31) -> 2773115 | D32: =SUM(D23:D31) -> 641452
A34: TABLE C — Encours de dépôts et remboursements par ligne (document 'FOCUS CMT à/h de 1 000 MXOF', p.2)
A35: En MXOF | B35: 2025 | C35: 2026 | D35: 2027 | E35: 2028 | F35: 2029 | G35: 2030
A36: Encours de dépôts | B36: 86000 | C36: 86000 | D36: 86000 | E36: 86000 | F36: 86000 | G36: 86000
A37: Remboursement BlueOrchard | B37: 978 | C37: 79 | D37: 79 | E37: 859
A38: Remboursement CDC | B38: 67 | C38: 135 | D38: 135 | E38: 481 | F38: 828 | G38: 414
A39: Remboursement Grameen | B39: 158 | C39: 172 | D39: 172 | E39: 970 | F39: 885
A40: Remboursement IDH | B40: 136 | C40: 136 | D40: 136 | E40: 136 | F40: 136 | G40: 164
A41: Remboursement BACI | B41: 923 | C41: 923 | D41: 620
A42: Remboursement SANAD | B42: 881 | C42: 827
A43: Remboursement SGCI 1 (CMT existant 2 500 MXOF) | B43: 158 | C43: 672 | D43: 672 | E43: 672 | F43: 504
A44: Remboursement SGCI 2 (nouveau CMT 1 000 MXOF) | C44: 324 | D44: 556 | E44: 556 | F44: 232
A45: Total remboursements (formule) | B45: =SUM(B37:B44) -> 3301 | C45: =SUM(C37:C44) -> 3268 | D45: =SUM(D37:D44) -> 2370 | E45: =SUM(E37:E44) -> 3674 | F45: =SUM(F37:F44) -> 2585 | G45: =SUM(G37:G44) -> 578
A46: Résiduel (Encours dépôts − Total remboursements) | B46: =B36-B45 -> 82699 | C46: =C36-C45 -> 82732 | D46: =D36-D45 -> 83630 | E46: =E36-E45 -> 82326 | F46: =F36-F45 -> 83415 | G46: =G36-G45 -> 85422
...

Sheet Exposition et recommandation
A1: ADVANS CI — Tableau d'exposition et recommandation au 14/07/2026
A3: Note NOVA DE/DL : 6/6+ sur base des EF 2023, valide jusqu'au 19/03/2026 puis prorogée au 19/06/2026.
A4: ⚠ Notation expirée depuis le 19/06/2026 — à faire renouveler avant présentation en comité (aujourd'hui : 14/07/2026, soit ~1 mois de retard).
A5: Note calculée (7+/7+) ≠ projet DCE (6-/6-) ≠ recommandation retenue (7/7, plus prudente, motivée par des « difficultés dans l'utilisation des lignes »).
A6: ⚠ Contradiction à lever : le focus détaillé sur l'usage des lignes (12 derniers mois) décrit un usage propre et sans incident — à confronter avec le motif invoqué pour la note 7/7.
A8: TABLEAU D'EXPOSITION (En Millions XOF)
A9: Ligne | B9: Engmts au 14/07/2026 | C9: Précédentes Aut. | D9: Échéance | E9: Aut. Sollicitées | F9: Recommandation (Montant) | G9: Maturité/DAV
A10: Découvert | B10: Sc : 2 490 | C10: 600 | D10: 31/10/2026 | E10: 600 | F10: 600 | G10: 12 mois
A11: Spot | B11: - | C11: 1000 | D11: 31/10/2026 | E11: 3500 | F11: 3500 | G11: 3 mois
A12: Cautions diverses | B12: 25 | C12: 25 | E12: 25 | F12: 25 | G12: 12 mois
A13: CMT 1 (montant initial : 2 500) | B13: 1385 | C13: 1385 | D13: 15/07/2028 | G13: Échéance le 15/07/2028
A14: NEW CMT | B14: - | C14: - | E14: 1000 | F14: 1000 | G14: 36 mois
A15: TOTAL Aut. Sollicitées (formule) | E15: =SUM(E10:E14) -> 5125
A16: Contrôle — doit reconstituer 5 125 MXOF (valeur client)
A18: Total exposition client (donnée client, incl. Sc découvert 2 490) | B18: 6510
A20: Encours réel CMT 1 au 14/07/2026 (donnée client, remplace la reconstitution par formule de l'onglet Focus) | F20: 1385
A21: Capital déjà amorti = 2 500 − 1 385 = 1 115 MXOF, soit 44,6% du montant initial en ~1 an.

Sheet Focus CMT 1000 MXOF
A2: FOCUS — Demande de CMT à hauteur de 1 000 MXOF (ADVANS CI)
A3: Toutes les cellules noires sont des formules liées à l'onglet 'Données sources'. Cellules jaunes = à compléter par le chargé d'affaires.
A5: En MXOF | B5: 2024 | C5: 2025 | D5: 2026 | E5: 2027 | F5: 2028 | G5: 2029 | H5: 2030
A6: 1. Décomposition des lignes SGCI
A7: SGCI 1 — CMT existant, amortissement (2 500 MXOF, 2025) | B7: ='Données sources'!#REF! -> #REF! | C7: ='Données sources'!B43 -> 158 | D7: ='Données sources'!C43 -> 672 | E7: ='Données sources'!D43 -> 672 | F7: ='Données sources'!E43 -> 672 | G7: ='Données sources'!F43 -> 504 | H7: ='Données sources'!G43 -> 0
A8: Encours réel CMT 1 au 14/07/2026 (donnée client — cf. onglet 'Exposition et recommandation') | D8: ='Exposition et recommandation'!F20 -> 1385
A9: Écart vs amortissement cumulé reconstitué à date (contrôle de cohérence, doit être proche) : capital initial 2 500 − encours 1 385 = 1 115 amorti à date.
A10: SGCI 2 — Nouveau CMT (1 000 MXOF, demande en cours) | B10: ='Données sources'!#REF! -> #REF! | C10: ='Données sources'!B44 -> 0 | D10: ='Données sources'!C44 -> 324 | E10: ='Données sources'!D44 -> 556 | F10: ='Données sources'!E44 -> 556 | G10: ='Données sources'!F44 -> 232 | H10: ='Données sources'!G44 -> 0
A11: Total service de dette SGCI (SGCI 1 + SGCI 2) | B11: =B7+B10 -> #REF! | C11: =C7+C10 -> 158 | D11: =D7+D10 -> 996 | E11: =E7+E10 -> 1228 | F11: =F7+F10 -> 1228 | G11: =G7+G10 -> 736 | H11: =H7+H10 -> 0
A13: 2. Poids de la nouvelle ligne dans le sous-ensemble de bailleurs suivi (Table C)
A14: Note : ce calcul porte sur le périmètre partiel de la Table C (BlueOrchard, CDC, Grameen, IDH, BACI, SANAD, SGCI) — il ne représente pas le poids dans la dette institutionnelle totale (voir section 3 pour la couverture globale correcte).
A15: Total remboursements toutes lignes (Table C) | B15: ='Données sources'!#REF! -> #REF! | C15: ='Données sources'!B45 -> 3301 | D15: ='Données sources'!C45 -> 3268 | E15: ='Données sources'!D45 -> 2370 | F15: ='Données sources'!E45 -> 3674 | G15: ='Données sources'!F45 -> 2585 | H15: ='Données sources'!G45 -> 578
A16: Poids de SGCI 2 (nouvelle ligne) dans le total | B16: =IFERROR(B10/B15,"-") -> - | C16: =IFERROR(C10/C15,"-") -> 0 | D16: =IFERROR(D10/D15,"-") -> 0.099143207 | E16: =IFERROR(E10/E15,"-") -> 0.23459916 | F16: =IFERROR(F10/F15,"-") -> 0.1513337 | G16: =IFERROR(G10/G15,"-") -> 0.089748549 | H16: =IFERROR(H10/H15,"-") -> 0
A18: 3. Couverture de la dette globale — CAPITAL SEUL (voir 3bis pour le DSCR réel avec intérêts)
A19: ⚠ Point méthodologique : la Table C (BlueOrchard, CDC, Grameen, IDH, BACI, SANAD, SGCI) ne couvre qu'un sous-ensemble partiel des bailleurs. Le dénominateur retenu ci-dessous est l'amortissement TOTAL de la dette institutionnelle (Table A/B, qui inclut aussi NSIA, BICICI, BIO 1-3), auquel on ajoute la nouvelle ligne SGCI 2 — c'est le périmètre correct pour un ratio de couverture globale.
A21: Cash-flow disponible = Coût du risque + RN — converti en MXOF (formule) | B21: =('Données sources'!#REF!+'Données sources'!#REF!)/1000 -> #REF! | C21: =('Données sources'!B7+'Données sources'!B8)/1000 -> 5.346 | D21: =('Données sources'!C7+'Données sources'!C8)/1000 -> 4.109 | E21: =('Données sources'!D7+'Données sources'!D8)/1000 -> 4.109
A22: Contrôle — doit reconstituer 4 290 / 4 818 / 5 060 / 5 060 MXOF (Cash-flow tel que fourni par le client, Table A).
A23: ⚠ AUCUNE VISIBILITÉ RÉELLE sur 2026 et 2027 : Advans CI n'a communiqué de données financières auditées/observées que jusqu'à 2025 (cf. Table D, onglet Données sources). Les valeurs 2026-2027 ci-dessus (orange) sont une PROJECTION issue d'un document de demande CMT antérieur, non recoupée avec des données réelles — à traiter comme indicative uniquement, pas comme un engagement de résultat.
A25: Amortissement dette totale existante — CAPITAL uniquement, hors intérêts (converti en MXOF) | B25: ='Données sources'!#REF!/1000 -> #REF! | C25: ='Données sources'!B11/1000 -> 3.301 | D25: ='Données sources'!C11/1000 -> 3.268 | E25: ='Données sources'!D11/1000 -> 2.37
A26: Amortissement total (capital) AVEC la nouvelle ligne (+ SGCI 2) | B26: =IF(B25="","-",B25+B10) -> #REF! | C26: =IF(C25="","-",C25+C10) -> 3.301 | D26: =IF(D25="","-",D25+D10) -> 327.268 | E26: =IF(E25="","-",E25+E10) -> 558.37 | F26: =IF(F25="","-",F25+F10) -> - | G26: =IF(G25="","-",G25+G10) -> - | H26: =IF(H25="","-",H25+H10) -> -
A28: Couverture CAPITAL SEUL, sans la nouvelle ligne (Cash-flow / Amortissement capital) | B28: =IFERROR(B21/B25,"-") -> - | C28: =IFERROR(C21/C25,"-") -> 1.6195092 | D28: =IFERROR(D21/D25,"-") -> 1.2573439 | E28: =IFERROR(E21/E25,"-") -> 1.7337553 | F28: =IFERROR(F21/F25,"-") -> - | G28: =IFERROR(G21/G25,"-") -> - | H28: =IFERROR(H21/H25,"-") -> -
A29: Couverture CAPITAL SEUL, AVEC la nouvelle ligne (Cash-flow / Amortissement capital total) | B29: =IFERROR(B21/B26,"-") -> - | C29: =IFERROR(C21/C26,"-") -> 1.6195092 | D29: =IFERROR(D21/D26,"-") -> 0.012555459 | E29: =IFERROR(E21/E26,"-") -> 0.0073589197 | F29: =IFERROR(F21/F26,"-") -> - | G29: =IFERROR(G21/G26,"-") -> - | H29: =IFERROR(H21/H26,"-") -> -
A30: Impact de la nouvelle ligne sur la couverture capital seul (points) | B30: =IFERROR(B29-B28,"-") -> - | C30: =IFERROR(C29-C28,"-") -> 0 | D30: =IFERROR(D29-D28,"-") -> -1.2447885 | E30: =IFERROR(E29-E28,"-") -> -1.7263964 | F30: =IFERROR(F29-F28,"-") -> - | G30: =IFERROR(G29-G28,"-") -> - | H30: =IFERROR(H29-H28,"-") -> -
A31: Contrôle — Couverture 'sans' doit reconstituer 1,10 / 1,05 / 1,82 / 7,89 (valeurs Table A telles que fournies par le client)
A33: 3bis. Couverture réelle du service de la dette (DSCR) — capital + intérêts ESTIMÉS
A34: Méthode : les intérêts par ligne SGCI ne sont pas communiqués. On les ESTIME en appliquant le taux d'intérêt implicite d'Advans CI (Table E, calculé à partir de son compte de résultat et bilan AUDITÉS : intérêts payés ÷ encours moyen d'emprunts institutionnels, tous bailleurs) à l'encours moyen SGCI reconstitué à partir de l'échéancier de capital réel (Table C). Cellules oranges = estimation justifiée, à remplacer par un taux contractuel réel dès qu'il est communiqué.
A36: Encours CMT SGCI 1 fin d'année (2 500 MXOF initial − cumul capital remboursé) | B36: - | C36: =MAX(0,2500-SUM('Données sources'!$B43:B43)) -> 2342 | D36: =MAX(0,2500-SUM('Données sources'!$B43:C43)) -> 1670 | E36: =MAX(0,2500-SUM('Données sources'!$B43:D43)) -> 998 | F36: =MAX(0,2500-SUM('Données sources'!$B43:E43)) -> 326 | G36: =MAX(0,2500-SUM('Données sources'!$B43:F43)) -> 0 | H36: =MAX(0,2500-SUM('Données sources'!$B43:G43)) -> 0
A37: Encours CMT SGCI 2 fin d'année (1 000 MXOF initial − cumul capital remboursé) | B37: - | C37: - | D37: =MAX(0,1000-SUM('Données sources'!$C44:C44)) -> 676 | E37: =MAX(0,1000-SUM('Données sources'!$C44:D44)) -> 120 | F37: =MAX(0,1000-SUM('Données sources'!$C44:E44)) -> 0 | G37: =MAX(0,1000-SUM('Données sources'!$C44:F44)) -> 0 | H37: =MAX(0,1000-SUM('Données sources'!$C44:G44)) -> 0
A38: Encours moyen SGCI (base de calcul des intérêts, capital initial le 1er exercice de tirage) | B38: - | C38: =AVERAGE(2500,C36) -> 2421 | D38: =AVERAGE(C36,D36)+AVERAGE(1000,D37) -> 2844 | E38: =AVERAGE(D36,E36)+AVERAGE(D37,E37) -> 1732 | F38: =AVERAGE(E36,F36)+AVERAGE(E37,F37) -> 722 | G38: =AVERAGE(F36,G36)+AVERAGE(F37,G37) -> 163 | H38: =AVERAGE(G36,H36)+AVERAGE(G37,H37) -> 0
A39: Taux d'intérêt implicite retenu (Table E, moyenne 2023-2024 sur dette institutionnelle Advans CI) | B39: ='Données sources'!#REF! -> #REF! | C39: ='Données sources'!#REF! -> #REF! | D39: ='Données sources'!#REF! -> #REF! | E39: ='Données sources'!#REF! -> #REF! | F39: ='Données sources'!#REF! -> #REF! | G39: ='Données sources'!#REF! -> #REF! | H39: ='Données sources'!#REF! -> #REF!
A40: Intérêts estimés SGCI (Encours moyen × Taux implicite) | B40: =IF(B38="-",0,B38*B39) -> 0 | C40: =IF(C38="-",0,C38*C39) -> #REF! | D40: =IF(D38="-",0,D38*D39) -> #REF! | E40: =IF(E38="-",0,E38*E39) -> #REF! | F40: =IF(F38="-",0,F38*F39) -> #REF! | G40: =IF(G38="-",0,G38*G39) -> #REF! | H40: =IF(H38="-",0,H38*H39) -> #REF!
A42: Service de la dette total SGCI estimé (capital SGCI 1+2 + intérêts estimés) — formule | B42: =B7+B10+B40 -> #REF! | C42: =C7+C10+C40 -> #REF! | D42: =D7+D10+D40 -> #REF! | E42: =E7+E10+E40 -> #REF! | F42: =F7+F10+F40 -> #REF! | G42: =G7+G10+G40 -> #REF! | H42: =H7+H10+H40 -> #REF!
A43: DSCR estimé, exposition SGCI seule (Cash-flow total Advans CI / Service de la dette SGCI, capital + intérêts estimés) | B43: =IF(B21="","-",IFERROR(B21/B42,"-")) -> #REF! | C43: =IF(C21="","-",IFERROR(C21/C42,"-")) -> - | D43: =IF(D21="","-",IFERROR(D21/D42,"-")) -> - | E43: =IF(E21="","-",IFERROR(E21/E42,"-")) -> - | F43: =IF(F21="","-",IFERROR(F21/F42,"-")) -> - | G43: =IF(G21="","-",IFERROR(G21/G42,"-")) -> - | H43: =IF(H21="","-",IFERROR(H21/H42,"-")) -> -
A44: Note : ce DSCR porte spécifiquement sur l'exposition SGCI (capital + intérêts estimés des 2 lignes CMT), rapportée au cash-flow TOTAL d'Advans CI — un angle complémentaire à la couverture globale de la section 3 (qui porte sur l'ensemble de la dette institutionnelle, capital seul).
A46: 4. Repères et lecture
A47: • INTÉRÊTS ESTIMÉS, PAS RÉELS : la section 3 (couverture capital seul) reste optimiste par construction. La section 3bis comble ce trou avec une ESTIMATION justifiée (taux implicite Advans CI × encours moyen SGCI), mais ce n'est pas un taux contractuel — à remplacer dès que le chargé d'affaires communique le taux réel des lignes SGCI.
A48: • AUCUNE VISIBILITÉ RÉELLE sur 2026-2027 : les seules données financières réelles/auditées d'Advans CI couvrent 2023-2025 (Table D). Les cellules orange (Cash-flow, Amortissement 2026-2027 en section 3) sont une projection non vérifiée d'un document antérieur — à confirmer avec le chargé d'affaires.
A49: • Couverture de dette 2024-2025 déjà tendue (1,10x / 1,05x capital seul, cf. Table A) avant même l'ajout de la nouvelle ligne SGCI 2 — marge de sécurité faible, et ce sans compter les intérêts.
A50: • L'amortissement SGCI 2 n'est pas linéaire : il monte à 556 MXOF en 2027-2028 avant de redescendre à 232 en 2029 — profil à faire confirmer (différé initial ?).
A51: • Le RN 2024 utilisé dans le Cash-flow (Table A, 2 773 281 KXOF) est ~40% supérieur au RN 2024 réellement audité (1 657 371 KXOF, cf. Table D) — la fiabilité de cette projection est donc déjà mise en doute par un écart avéré, y compris sur l'année où elle est vérifiable.
...
