Workbook

Sheet Modèle Original
A1: Repris automatiquement sur la notice financière
A2: Hypothèses de modélisation à renseigner
A3: Voir commentaires sur la cellule
A4: À calculer et saisir par l'implantation en fonction du taux
A5: À renseigner en fonction des éléments communiqués par le client
A6: À renseigner par l'implantation : amortissement en capital
A7: Hypothèses retenues pour les modalités de financement
B9: M XOF — Exercice 12 mois | C9: 2024 | D9: 2025 | E9: 2026 | F9: 2027 | G9: 2028 | H9: 2029 | I9: 2030 | J9: Total / Moy.
C10: Audité | D10: Provisoire | E10: Projeté | F10: Projeté | G10: Projeté | H10: Projeté | I10: Projeté
A11: CHIFFRE D'AFFAIRES
B12: Hypothèse d'évolution du CA | C12: - | D12: =(Hypothèses!B9-Hypothèses!B8)/Hypothèses!B8 -> 0.11047149 | E12: =Hypothèses!B10 -> 0.08 | F12: =Hypothèses!B11 -> 0.07 | G12: =Hypothèses!B12 -> 0.05 | H12: =Hypothèses!B12 -> 0.05 | I12: =Hypothèses!B12 -> 0.05 | J12: -
B13: CHIFFRE D'AFFAIRES NET | C13: =Hypothèses!B8 -> 38818.224 | D13: =Hypothèses!B9 -> 43106.531 | E13: =D13*(1+E12) -> 46555.053 | F13: =E13*(1+F12) -> 49813.907 | G13: =F13*(1+G12) -> 52304.603 | H13: =G13*(1+H12) -> 54919.833 | I13: =H13*(1+I12) -> 57665.824 | J13: =SUM(C13:I13) -> 343183.98
B14: Poids achats & var. stocks / CA | C14: 0.6258 | D14: =Hypothèses!B15 -> 0.63 | E14: =Hypothèses!B15 -> 0.63 | F14: =Hypothèses!B15 -> 0.63 | G14: =Hypothèses!B15 -> 0.63 | H14: =Hypothèses!B15 -> 0.63 | I14: =Hypothèses!B15 -> 0.63 | J14: -
B15: − Achats & var. stocks de matières | C15: =C13*C14 -> 24292.445 | D15: =D13*D14 -> 27157.115 | E15: =E13*E14 -> 29329.684 | F15: =F13*F14 -> 31382.762 | G15: =G13*G14 -> 32951.9 | H15: =H13*H14 -> 34599.495 | I15: =I13*I14 -> 36329.469 | J15: =SUM(C15:I15) -> 216042.87
B16: Poids frais de personnel / CA | C16: =Hypothèses!B16 -> 0.1215 | D16: =Hypothèses!B16 -> 0.1215 | E16: =Hypothèses!B16 -> 0.1215 | F16: =Hypothèses!B16 -> 0.1215 | G16: =Hypothèses!B16 -> 0.1215 | H16: =Hypothèses!B16 -> 0.1215 | I16: =Hypothèses!B16 -> 0.1215 | J16: -
B17: − Frais de personnel | C17: =C13*C16 -> 4716.4142 | D17: =D13*D16 -> 5237.4435 | E17: =E13*E16 -> 5656.439 | F17: =F13*F16 -> 6052.3897 | G17: =G13*G16 -> 6355.0092 | H17: =H13*H16 -> 6672.7597 | I17: =I13*I16 -> 7006.3977 | J17: =SUM(C17:I17) -> 41696.853
B18: Poids charges externes / CA | C18: =Hypothèses!B17 -> 0.0725 | D18: =Hypothèses!B17 -> 0.0725 | E18: =Hypothèses!B17 -> 0.0725 | F18: =Hypothèses!B17 -> 0.0725 | G18: =Hypothèses!B17 -> 0.0725 | H18: =Hypothèses!B17 -> 0.0725 | I18: =Hypothèses!B17 -> 0.0725 | J18: -
B19: − Charges externes | C19: =C13*C18 -> 2814.3212 | D19: =D13*D18 -> 3125.2235 | E19: =E13*E18 -> 3375.2414 | F19: =F13*F18 -> 3611.5083 | G19: =G13*G18 -> 3792.0837 | H19: =H13*H18 -> 3981.6879 | I19: =I13*I18 -> 4180.7723 | J19: =SUM(C19:I19) -> 24880.838
B20: +/− Autres produits & charges d'exploitation | C20: 0 | D20: 0 | E20: 0 | F20: 0 | G20: 0 | H20: 0 | I20: 0 | J20: -
B21: % EBE/CA calculé | C21: =IF(C13=0,"-",(C13-C15-C17-C19+C20)/C13) -> 0.1802 | D21: =(D13-D15-D17-D19+D20)/D13 -> 0.176 | E21: =(E13-E15-E17-E19+E20)/E13 -> 0.176 | F21: =(F13-F15-F17-F19+F20)/F13 -> 0.176 | G21: =(G13-G15-G17-G19+G20)/G13 -> 0.176 | H21: =(H13-H15-H17-H19+H20)/H13 -> 0.176 | I21: =(I13-I15-I17-I19+I20)/I13 -> 0.176 | J21: -
B22: EXCÉDENT BRUT D'EXPLOITATION (EBE) | C22: =C13-C15-C17-C19+C20 -> 6995.044 | D22: =D13-D15-D17-D19+D20 -> 7586.7495 | E22: =E13-E15-E17-E19+E20 -> 8193.6894 | F22: =F13-F15-F17-F19+F20 -> 8767.2477 | G22: =G13-G15-G17-G19+G20 -> 9205.6101 | H22: =H13-H15-H17-H19+H20 -> 9665.8906 | I22: =I13-I15-I17-I19+I20 -> 10149.185 | J22: =SUM(C22:I22) -> 60563.416
A23: DOTATIONS AUX AMORTISSEMENTS
B24: Dont moy. amortissements corporels (derniers exercices) | C24: =Hypothèses!B20 -> 2368 | D24: =Hypothèses!B20 -> 2368 | E24: =Hypothèses!B20 -> 2368 | F24: =Hypothèses!B20 -> 2368 | G24: =Hypothèses!B20 -> 2368 | H24: =Hypothèses!B20 -> 2368 | I24: =Hypothèses!B20 -> 2368 | J24: -
B25: Dont amortissements liés aux nouveaux Capex amortissables | C25: 0 | D25: 0 | E25: =IFERROR(Hypothèses!B39/Hypothèses!C39,0)+IFERROR(Hypothèses!B40/Hypothèses!C40,0)+IFERROR(Hypothèses!B41/Hypothèses!C41,0) -> 37.572 | F25: =IFERROR(Hypothèses!B39/Hypothèses!C39,0)+IFERROR(Hypothèses!B40/Hypothèses!C40,0)+IFERROR(Hypothèses!B41/Hypothèses!C41,0) -> 37.572 | G25: =IFERROR(Hypothèses!B39/Hypothèses!C39,0)+IFERROR(Hypothèses!B40/Hypothèses!C40,0)+IFERROR(Hypothèses!B41/Hypothèses!C41,0) -> 37.572 | H25: =IFERROR(Hypothèses!B39/Hypothèses!C39,0)+IFERROR(Hypothèses!B40/Hypothèses!C40,0)+IFERROR(Hypothèses!B41/Hypothèses!C41,0) -> 37.572 | I25: =IFERROR(Hypothèses!B39/Hypothèses!C39,0)+IFERROR(Hypothèses!B40/Hypothèses!C40,0)+IFERROR(Hypothèses!B41/Hypothèses!C41,0) -> 37.572 | J25: -
B26: − Dotations aux amortissements (Total) | C26: =C24+C25 -> 2368 | D26: =D24+D25 -> 2368 | E26: =E24+E25 -> 2405.572 | F26: =F24+F25 -> 2405.572 | G26: =G24+G25 -> 2405.572 | H26: =H24+H25 -> 2405.572 | I26: =I24+I25 -> 2405.572 | J26: =SUM(C26:I26) -> 16763.86
A27: RÉSULTAT FINANCIER
B28: Dont moy. résultat financier (derniers exercices) | C28: -507 | D28: -507 | E28: -507 | F28: -507 | G28: -507 | H28: -507 | I28: -507 | J28: -
B29: Dont intérêts financiers liés aux nouvelles dettes | C29: 0 | D29: 0 | E29: =-Hypothèses!B29*Hypothèses!B31 -> -375 | F29: =-Hypothèses!B29*Hypothèses!B31 -> -375 | G29: =-Hypothèses!B29*Hypothèses!B31 -> -375 | H29: =-Hypothèses!B29*Hypothèses!B31 -> -375 | I29: =-Hypothèses!B29*Hypothèses!B31 -> -375 | J29: -
B30: + Résultat financier (Total) | C30: =C28+C29 -> -507 | D30: =D28+D29 -> -507 | E30: =E28+E29 -> -882 | F30: =F28+F29 -> -882 | G30: =G28+G29 -> -882 | H30: =H28+H29 -> -882 | I30: =I28+I29 -> -882 | J30: -
B31: +/− Autres produits & charges | C31: 0 | D31: 0 | E31: 0 | F31: 0 | G31: 0 | H31: 0 | I31: 0 | J31: -
B32: RÉSULTAT COURANT AVANT IMPÔT | C32: =C22-C26+C30+C31 -> 4120.044 | D32: =D22-D26+D30+D31 -> 4711.7495 | E32: =E22-E26+E30+E31 -> 4906.1174 | F32: =F22-F26+F30+F31 -> 5479.6757 | G32: =G22-G26+G30+G31 -> 5918.0381 | H32: =H22-H26+H30+H31 -> 6378.3186 | I32: =I22-I26+I30+I31 -> 6861.6131 | J32: =SUM(C32:I32) -> 38375.556
B33: − Impôt sur les sociétés (IS) | C33: =IF(C32>0,C32*Hypothèses!B34,0) -> 1030.011 | D33: =IF(D32>0,D32*Hypothèses!B34,0) -> 1177.9374 | E33: =IF(E32>0,E32*Hypothèses!B34,0) -> 1226.5294 | F33: =IF(F32>0,F32*Hypothèses!B34,0) -> 1369.9189 | G33: =IF(G32>0,G32*Hypothèses!B34,0) -> 1479.5095 | H33: =IF(H32>0,H32*Hypothèses!B34,0) -> 1594.5796 | I33: =IF(I32>0,I32*Hypothèses!B34,0) -> 1715.4033 | J33: =SUM(C33:I33) -> 9593.8891
B34: RÉSULTAT NET | C34: =C32-C33 -> 3090.033 | D34: =D32-D33 -> 3533.8121 | E34: =E32-E33 -> 3679.5881 | F34: =F32-F33 -> 4109.7568 | G34: =G32-G33 -> 4438.5285 | H34: =H32-H33 -> 4783.7389 | I34: =I32-I33 -> 5146.2098 | J34: =SUM(C34:I34) -> 28781.667
B35: MARGE BRUTE D'AUTOFINANCEMENT (MBA) | C35: =C34+C26 -> 5458.033 | D35: =D34+D26 -> 5901.8121 | E35: =E34+E26 -> 6085.1601 | F35: =F34+F26 -> 6515.3288 | G35: =G34+G26 -> 6844.1005 | H35: =H34+H26 -> 7189.3109 | I35: =I34+I26 -> 7551.7818 | J35: =SUM(C35:I35) -> 45545.527
A36: VARIATION DU BESOIN EN FONDS DE ROULEMENT (BFR)
A37: (1) | B37: BFR en jours de CA | C37: 246 | D37: =Hypothèses!B23+Hypothèses!B24-Hypothèses!B25 -> 185 | E37: =Hypothèses!B23+Hypothèses!B24-Hypothèses!B25 -> 185 | F37: =Hypothèses!B23+Hypothèses!B24-Hypothèses!B25 -> 185 | G37: =Hypothèses!B23+Hypothèses!B24-Hypothèses!B25 -> 185 | H37: =Hypothèses!B23+Hypothèses!B24-Hypothèses!B25 -> 185 | I37: =Hypothèses!B23+Hypothèses!B24-Hypothèses!B25 -> 185 | J37: -
B38: BFR en montant | C38: =C13*C37/365 -> 26162.419 | D38: =D13*D37/365 -> 21848.516 | E38: =E13*E37/365 -> 23596.397 | F38: =F13*F37/365 -> 25248.145 | G38: =G13*G37/365 -> 26510.552 | H38: =H13*H37/365 -> 27836.08 | I38: =I13*I37/365 -> 29227.884 | J38: -
B39: − Variation BFR (− = besoin supplémentaire) | C39: =C38-26144.985 -> 17.434463 | D39: =D38-C38 -> -4313.9038 | E39: =E38-D38 -> 1747.8813 | F39: =F38-E38 -> 1651.7478 | G39: =G38-F38 -> 1262.4072 | H39: =H38-G38 -> 1325.5276 | I39: =I38-H38 -> 1391.804 | J39: =SUM(C39:I39) -> 3082.8986
A40: (1) | B40: CASH FLOW D'EXPLOITATION (CFE = MBA − ΔBFR) | C40: =C35-C39 -> 5440.5985 | D40: =D35-D39 -> 10215.716 | E40: =E35-E39 -> 4337.2788 | F40: =F35-F39 -> 4863.581 | G40: =G35-G39 -> 5581.6933 | H40: =H35-H39 -> 5863.7833 | I40: =I35-I39 -> 6159.9778 | J40: =SUM(C40:I40) -> 42462.629
A41: INVESTISSEMENTS (CAPEX)
...

Sheet Présentation Dossier
A1: SIPPEC — TABLEAU DE FLUX PRÉVISIONNELS & CASH FLOW COVER | Montants en M XOF
A2: Norme comptable OHADA | Comptes audités 2024 | Hypothèses modélisées — Les cellules jaunes (onglet Hypothèses) font varier l'intégralité des projections
C3: ◀ HISTORIQUE ▶ | E3: ◀ PROJECTIONS (varient selon Hypothèses) ▶ | J3: TOTAL
B4: M XOF | C4: 2024 | D4: 2025 | E4: 2026 | F4: 2027 | G4: 2028 | H4: 2029 | I4: 2030 | J4: 2026→2030
C5: Audité | D5: Provisoire | E5: Projeté | F5: Projeté | G5: Projeté | H5: Projeté | I5: Projeté
A6: I. COMPTE DE RÉSULTAT PRÉVISIONNEL
B7: CHIFFRE D'AFFAIRES | C7: ='Modèle Amélioré'!C13 -> 38818.224 | D7: ='Modèle Amélioré'!D13 -> 43106.531 | E7: ='Modèle Amélioré'!E13 -> 46555.053 | F7: ='Modèle Amélioré'!F13 -> 49813.907 | G7: ='Modèle Amélioré'!G13 -> 52304.603 | H7: ='Modèle Amélioré'!H13 -> 54919.833 | I7: ='Modèle Amélioré'!I13 -> 57665.824 | J7: -
B8: Taux de croissance CA | C8: ='Modèle Amélioré'!C12 -> - | D8: ='Modèle Amélioré'!D12 -> 0.11047149 | E8: ='Modèle Amélioré'!E12 -> 0.08 | F8: ='Modèle Amélioré'!F12 -> 0.07 | G8: ='Modèle Amélioré'!G12 -> 0.05 | H8: ='Modèle Amélioré'!H12 -> 0.05 | I8: ='Modèle Amélioré'!I12 -> 0.05 | J8: -
B9: Poids achats / CA | C9: ='Modèle Amélioré'!C14 -> 0.6258 | D9: ='Modèle Amélioré'!D14 -> 0.63 | E9: ='Modèle Amélioré'!E14 -> 0.63 | F9: ='Modèle Amélioré'!F14 -> 0.63 | G9: ='Modèle Amélioré'!G14 -> 0.63 | H9: ='Modèle Amélioré'!H14 -> 0.63 | I9: ='Modèle Amélioré'!I14 -> 0.63 | J9: -
B10: − Achats & var. stocks | C10: ='Modèle Amélioré'!C15 -> 24292.445 | D10: ='Modèle Amélioré'!D15 -> 27157.115 | E10: ='Modèle Amélioré'!E15 -> 29329.684 | F10: ='Modèle Amélioré'!F15 -> 31382.762 | G10: ='Modèle Amélioré'!G15 -> 32951.9 | H10: ='Modèle Amélioré'!H15 -> 34599.495 | I10: ='Modèle Amélioré'!I15 -> 36329.469 | J10: =SUM(E10:I10) -> 164593.31
B11: Poids frais personnel / CA | C11: ='Modèle Amélioré'!C16 -> 0.1215 | D11: ='Modèle Amélioré'!D16 -> 0.1215 | E11: ='Modèle Amélioré'!E16 -> 0.1215 | F11: ='Modèle Amélioré'!F16 -> 0.1215 | G11: ='Modèle Amélioré'!G16 -> 0.1215 | H11: ='Modèle Amélioré'!H16 -> 0.1215 | I11: ='Modèle Amélioré'!I16 -> 0.1215 | J11: -
B12: − Frais de personnel | C12: ='Modèle Amélioré'!C17 -> 4716.4142 | D12: ='Modèle Amélioré'!D17 -> 5237.4435 | E12: ='Modèle Amélioré'!E17 -> 5656.439 | F12: ='Modèle Amélioré'!F17 -> 6052.3897 | G12: ='Modèle Amélioré'!G17 -> 6355.0092 | H12: ='Modèle Amélioré'!H17 -> 6672.7597 | I12: ='Modèle Amélioré'!I17 -> 7006.3977 | J12: =SUM(E12:I12) -> 31742.995
B13: Poids charges externes / CA | C13: ='Modèle Amélioré'!C18 -> 0.0725 | D13: ='Modèle Amélioré'!D18 -> 0.0725 | E13: ='Modèle Amélioré'!E18 -> 0.0725 | F13: ='Modèle Amélioré'!F18 -> 0.0725 | G13: ='Modèle Amélioré'!G18 -> 0.0725 | H13: ='Modèle Amélioré'!H18 -> 0.0725 | I13: ='Modèle Amélioré'!I18 -> 0.0725 | J13: -
B14: − Charges externes | C14: ='Modèle Amélioré'!C19 -> 2814.3212 | D14: ='Modèle Amélioré'!D19 -> 3125.2235 | E14: ='Modèle Amélioré'!E19 -> 3375.2414 | F14: ='Modèle Amélioré'!F19 -> 3611.5083 | G14: ='Modèle Amélioré'!G19 -> 3792.0837 | H14: ='Modèle Amélioré'!H19 -> 3981.6879 | I14: ='Modèle Amélioré'!I19 -> 4180.7723 | J14: =SUM(E14:I14) -> 18941.293
B15: EXCÉDENT BRUT D'EXPLOITATION (EBE) | C15: ='Modèle Amélioré'!C22 -> 6995.044 | D15: ='Modèle Amélioré'!D22 -> 7586.7495 | E15: ='Modèle Amélioré'!E22 -> 8193.6894 | F15: ='Modèle Amélioré'!F22 -> 8767.2477 | G15: ='Modèle Amélioré'!G22 -> 9205.6101 | H15: ='Modèle Amélioré'!H22 -> 9665.8906 | I15: ='Modèle Amélioré'!I22 -> 10149.185 | J15: =SUM(E15:I15) -> 45981.623
B16: EBE / CA (%) | C16: ='Modèle Amélioré'!C21 -> 0.1802 | D16: ='Modèle Amélioré'!D21 -> 0.176 | E16: ='Modèle Amélioré'!E21 -> 0.176 | F16: ='Modèle Amélioré'!F21 -> 0.176 | G16: ='Modèle Amélioré'!G21 -> 0.176 | H16: ='Modèle Amélioré'!H21 -> 0.176 | I16: ='Modèle Amélioré'!I21 -> 0.176 | J16: -
B17: − Dotations amortissements | C17: ='Modèle Amélioré'!C26 -> 2368 | D17: ='Modèle Amélioré'!D26 -> 2368 | E17: ='Modèle Amélioré'!E26 -> 2405.572 | F17: ='Modèle Amélioré'!F26 -> 2405.572 | G17: ='Modèle Amélioré'!G26 -> 2405.572 | H17: ='Modèle Amélioré'!H26 -> 2405.572 | I17: ='Modèle Amélioré'!I26 -> 2405.572 | J17: =SUM(E17:I17) -> 12027.86
B18: + Résultat financier | C18: ='Modèle Amélioré'!C31 -> -507 | D18: ='Modèle Amélioré'!D31 -> -507 | E18: ='Modèle Amélioré'!E31 -> -1501.6185 | F18: ='Modèle Amélioré'!F31 -> -1407.8685 | G18: ='Modèle Amélioré'!G31 -> -1314.1185 | H18: ='Modèle Amélioré'!H31 -> -1220.3685 | I18: ='Modèle Amélioré'!I31 -> -1126.6185 | J18: =SUM(E18:I18) -> -6570.5925
B19: RÉSULTAT COURANT AVANT IMPÔT | C19: ='Modèle Amélioré'!C33 -> 4120.044 | D19: ='Modèle Amélioré'!D33 -> 4711.7495 | E19: ='Modèle Amélioré'!E33 -> 4286.4989 | F19: ='Modèle Amélioré'!F33 -> 4953.8072 | G19: ='Modèle Amélioré'!G33 -> 5485.9196 | H19: ='Modèle Amélioré'!H33 -> 6039.9501 | I19: ='Modèle Amélioré'!I33 -> 6616.9946 | J19: =SUM(E19:I19) -> 27383.17
B20: − Impôt sur les sociétés (25%) | C20: ='Modèle Amélioré'!C34 -> 1030.011 | D20: ='Modèle Amélioré'!D34 -> 1177.9374 | E20: ='Modèle Amélioré'!E34 -> 1071.6247 | F20: ='Modèle Amélioré'!F34 -> 1238.4518 | G20: ='Modèle Amélioré'!G34 -> 1371.4799 | H20: ='Modèle Amélioré'!H34 -> 1509.9875 | I20: ='Modèle Amélioré'!I34 -> 1654.2486 | J20: =SUM(E20:I20) -> 6845.7926
B21: RÉSULTAT NET | C21: ='Modèle Amélioré'!C35 -> 3090.033 | D21: ='Modèle Amélioré'!D35 -> 3533.8121 | E21: ='Modèle Amélioré'!E35 -> 3214.8742 | F21: ='Modèle Amélioré'!F35 -> 3715.3554 | G21: ='Modèle Amélioré'!G35 -> 4114.4397 | H21: ='Modèle Amélioré'!H35 -> 4529.9625 | I21: ='Modèle Amélioré'!I35 -> 4962.7459 | J21: =SUM(E21:I21) -> 20537.378
B22: Marge nette (%) | C22: ='Modèle Amélioré'!C59 -> -0.079898555 | D22: ='Modèle Amélioré'!D59 -> 0.036457754 | E22: ='Modèle Amélioré'!E59 -> 0.17461033 | F22: ='Modèle Amélioré'!F59 -> 0.20972666 | G22: ='Modèle Amélioré'!G59 -> 0.26092905 | H22: ='Modèle Amélioré'!H59 -> 0.31490315 | I22: ='Modèle Amélioré'!I59 -> 0.37112665 | J22: -
B23: MARGE BRUTE D'AUTOFINANCEMENT (MBA) | C23: ='Modèle Amélioré'!C36 -> 5458.033 | D23: ='Modèle Amélioré'!D36 -> 5901.8121 | E23: ='Modèle Amélioré'!E36 -> 5620.4462 | F23: ='Modèle Amélioré'!F36 -> 6120.9274 | G23: ='Modèle Amélioré'!G36 -> 6520.0117 | H23: ='Modèle Amélioré'!H36 -> 6935.5345 | I23: ='Modèle Amélioré'!I36 -> 7368.3179 | J23: =SUM(E23:I23) -> 32565.238
A25: II. BESOIN EN FONDS DE ROULEMENT (BFR) — Calculé par délais
B26: Délai clients (jours de CA) | C26: ='Modèle Amélioré'!C38 -> 181 | D26: ='Modèle Amélioré'!D38 -> 153 | E26: ='Modèle Amélioré'!E38 -> 175 | F26: ='Modèle Amélioré'!F38 -> 175 | G26: ='Modèle Amélioré'!G38 -> 175 | H26: ='Modèle Amélioré'!H38 -> 175 | I26: ='Modèle Amélioré'!I38 -> 175 | J26: -
B27: Délai stocks (jours de CA) | C27: ='Modèle Amélioré'!C39 -> 137 | D27: ='Modèle Amélioré'!D39 -> 177 | E27: ='Modèle Amélioré'!E39 -> 140 | F27: ='Modèle Amélioré'!F39 -> 140 | G27: ='Modèle Amélioré'!G39 -> 140 | H27: ='Modèle Amélioré'!H39 -> 140 | I27: ='Modèle Amélioré'!I39 -> 140 | J27: -
B28: Délai fournisseurs (jours d'achats) | C28: ='Modèle Amélioré'!C40 -> 133 | D28: ='Modèle Amélioré'!D40 -> 153 | E28: ='Modèle Amélioré'!E40 -> 130 | F28: ='Modèle Amélioré'!F40 -> 130 | G28: ='Modèle Amélioré'!G40 -> 130 | H28: ='Modèle Amélioré'!H40 -> 130 | I28: ='Modèle Amélioré'!I40 -> 130 | J28: -
B29: BFR en jours de CA (= Clients + Stocks − Fournisseurs) | C29: ='Modèle Amélioré'!C41 -> 185 | D29: ='Modèle Amélioré'!D41 -> 177 | E29: ='Modèle Amélioré'!E41 -> 185 | F29: ='Modèle Amélioré'!F41 -> 185 | G29: ='Modèle Amélioré'!G41 -> 185 | H29: ='Modèle Amélioré'!H41 -> 185 | I29: ='Modèle Amélioré'!I41 -> 185 | J29: -
B30: BFR en montant (M XOF) | C30: ='Modèle Amélioré'!C42 -> 19674.99 | D30: ='Modèle Amélioré'!D42 -> 20903.715 | E30: ='Modèle Amélioré'!E42 -> 23596.397 | F30: ='Modèle Amélioré'!F42 -> 25248.145 | G30: ='Modèle Amélioré'!G42 -> 26510.552 | H30: ='Modèle Amélioré'!H42 -> 27836.08 | I30: ='Modèle Amélioré'!I42 -> 29227.884 | J30: -
B31: − Variation BFR | C31: ='Modèle Amélioré'!C43 -> -6469.9948 | D31: ='Modèle Amélioré'!D43 -> 1228.7248 | E31: ='Modèle Amélioré'!E43 -> 2692.6819 | F31: ='Modèle Amélioré'!F43 -> 1651.7478 | G31: ='Modèle Amélioré'!G43 -> 1262.4072 | H31: ='Modèle Amélioré'!H43 -> 1325.5276 | I31: ='Modèle Amélioré'!I43 -> 1391.804 | J31: =SUM(E31:I31) -> 8324.1685
A32: (1) | B32: CASH FLOW D'EXPLOITATION (CFE = MBA − Δ BFR) | C32: ='Modèle Amélioré'!C44 -> 11928.028 | D32: ='Modèle Amélioré'!D44 -> 4673.0873 | E32: ='Modèle Amélioré'!E44 -> 2927.7642 | F32: ='Modèle Amélioré'!F44 -> 4469.1796 | G32: ='Modèle Amélioré'!G44 -> 5257.6044 | H32: ='Modèle Amélioré'!H44 -> 5610.0069 | I32: ='Modèle Amélioré'!I44 -> 5976.514 | J32: =SUM(E32:I32) -> 24241.069
A34: III. INVESTISSEMENTS (CAPEX)
B35: − Capex non amortissables | C35: ='Modèle Amélioré'!C46 -> 0 | D35: ='Modèle Amélioré'!D46 -> 0 | E35: ='Modèle Amélioré'!E46 -> 0 | F35: ='Modèle Amélioré'!F46 -> 0 | G35: ='Modèle Amélioré'!G46 -> 0 | H35: ='Modèle Amélioré'!H46 -> 0 | I35: ='Modèle Amélioré'!I46 -> 0 | J35: =SUM(E35:I35) -> 0
B36: − Capex amortissables (liés au financement) | C36: ='Modèle Amélioré'!C47 -> 0 | D36: ='Modèle Amélioré'!D47 -> 0 | E36: ='Modèle Amélioré'!E47 -> 375.72 | F36: ='Modèle Amélioré'!F47 -> 0 | G36: ='Modèle Amélioré'!G47 -> 0 | H36: ='Modèle Amélioré'!H47 -> 0 | I36: ='Modèle Amélioré'!I47 -> 0 | J36: =SUM(E36:I36) -> 375.72
A37: (1)-(2) | B37: FREE CASH FLOW | C37: ='Modèle Amélioré'!C49 -> 11928.028 | D37: ='Modèle Amélioré'!D49 -> 4673.0873 | E37: ='Modèle Amélioré'!E49 -> 2552.0442 | F37: ='Modèle Amélioré'!F49 -> 4469.1796 | G37: ='Modèle Amélioré'!G49 -> 5257.6044 | H37: ='Modèle Amélioré'!H49 -> 5610.0069 | I37: ='Modèle Amélioré'!I49 -> 5976.514 | J37: =SUM(E37:I37) -> 23865.349
A39: IV. SERVICE DE LA DETTE — Tableau d'amortissement intégré
B40: + Nouvelle dette débloquée | C40: ='Modèle Amélioré'!C51 -> 0 | D40: ='Modèle Amélioré'!D51 -> 0 | E40: ='Modèle Amélioré'!E51 -> 5000 | F40: ='Modèle Amélioré'!F51 -> 0 | G40: ='Modèle Amélioré'!G51 -> 0 | H40: ='Modèle Amélioré'!H51 -> 0 | I40: ='Modèle Amélioré'!I51 -> 0 | J40: =SUM(E40:I40) -> 5000
B41: − Dividendes distribués | C41: ='Modèle Amélioré'!C52 -> 0 | D41: ='Modèle Amélioré'!D52 -> 0 | E41: ='Modèle Amélioré'!E52 -> 0 | F41: ='Modèle Amélioré'!F52 -> 0 | G41: ='Modèle Amélioré'!G52 -> 0 | H41: ='Modèle Amélioré'!H52 -> 0 | I41: ='Modèle Amélioré'!I52 -> 0 | J41: =SUM(E41:I41) -> 0
A42: (3) | B42: CF DISPONIBLE AVANT SERVICE DE LA DETTE | C42: ='Modèle Amélioré'!C53 -> 11928.028 | D42: ='Modèle Amélioré'!D53 -> 4673.0873 | E42: ='Modèle Amélioré'!E53 -> 7552.0442 | F42: ='Modèle Amélioré'!F53 -> 4469.1796 | G42: ='Modèle Amélioré'!G53 -> 5257.6044 | H42: ='Modèle Amélioré'!H53 -> 5610.0069 | I42: ='Modèle Amélioré'!I53 -> 5976.514 | J42: =SUM(E42:I42) -> 28865.349
B43: Dont capital remboursé | C43: ='Modèle Amélioré'!C54 -> 0 | D43: ='Modèle Amélioré'!D54 -> 0 | E43: ='Modèle Amélioré'!E54 -> 0 | F43: ='Modèle Amélioré'!F54 -> 1250 | G43: ='Modèle Amélioré'!G54 -> 1250 | H43: ='Modèle Amélioré'!H54 -> 1250 | I43: ='Modèle Amélioré'!I54 -> 1250 | J43: =SUM(E43:I43) -> 5000
...

Sheet Demande & Cas Dégradé
A1: SIPPEC — ANALYSE DE LA CAPACITÉ DE REMBOURSEMENT | CAS DE BASE vs CAS DÉGRADÉ | M XOF
A2: CMT/CB/LB 5 000 M XOF | DVA 6 mois | Maturité 72 mois (6 ans) | Taux : à calculer implantation | Objet : financement programme investissement 2026 & refinancement | CREDAPP SIPPEC 03/2026 — Mariam ASSOUMOU / Arsène KABLAN
A4: I. PRÉSENTATION DE LA DEMANDE DE CRÉDIT
A5: Critère | B5: Caractéristique | C5: Justification analytique
A6: Nature | B6: CMT / Crédit-bail / Lease-back | C6: Financement d'équipements industriels (plasturgie + peinture) et refinancement de matériels acquis sur fonds propres en 2025/2026.
A7: Montant | B7: 5 000 M XOF (71% du projet) | C7: Montant global du programme : 7 000 M XOF. Autofinancement client : 2 000 M XOF (29%) financés sur flux d'activité. Cohérent avec la capacité de MBA du client (~5 000-6 000 M XOF/an).
A8: Différé en capital | B8: 6 mois (DVA) | C8: Différé justifié par les délais de livraison et mise en service des équipements importés (fournisseurs européens et américains). Permet de ne pas peser sur la trésorerie pendant la phase d'installation.
A9: Durée | B9: 72 mois (6 ans) | C9: Durée alignée sur la durée de vie économique des équipements (10 ans en normes OHADA). Un ratio durée/vie éco de 60% est prudent. Durée cohérente avec la MBA annuelle projetée de 5 500-6 500 M XOF.
A10: Objet du financement | B10: Plasturgie : lignes PEHD, fileuses, extrudeuses, presses injection — Peinture : unité de production vinylique VIBROFAC | C10: Investissements visant à porter la capacité de production de 60 000 à 117 700 tonnes (+57 700 T), soit +96%. Impact direct sur le CA : volume additionnel estimé à +20-25% à terme. Fournisseurs certifiés (WEBER, SICA, NOZUMI, EVERPLAST).
A11: Encours CMT existant à revoir | B11: 4 590 M XOF | C11: Encours issu de CMT antérieurs finançant les investissements initiaux. La revue est justifiée par la consolidation de la relation et la restructuration du profil de dette pour alléger les annuités sur la période de montée en régime des nouveaux investissements.
A12: Garanties | B12: À préciser — DSRA ≥ 2 échéances recommandé | C12: Compte tenu du BFR structurellement élevé (délais clients publics) et de la trésorerie déficitaire en 2026, la constitution d'un DSRA (Debt Service Reserve Account) équivalent à 2 échéances (capital + intérêts) est recommandée comme condition préalable au déblocage.
A14: II. HYPOTHÈSES COMPARÉES — CAS DE BASE (Client) vs CAS DÉGRADÉ (SGCI)
B15: Rubrique | C15: Justification analytique du cas dégradé | D15: 2026 | E15: 2027 | F15: 2028 | G15: 2029 | H15: 2030 | I15: 2031 | J15: 2032 | K15: 2026 | L15: 2027 | M15: 2028 | N15: 2029 | O15: 2030 | P15: 2031 | Q15: 2032
D16: CAS BASE | E16: CAS BASE | F16: CAS BASE | G16: CAS BASE | H16: CAS BASE | I16: CAS BASE | J16: CAS BASE | K16: CAS DÉGRADÉ | L16: CAS DÉGRADÉ | M16: CAS DÉGRADÉ | N16: CAS DÉGRADÉ | O16: CAS DÉGRADÉ | P16: CAS DÉGRADÉ | Q16: CAS DÉGRADÉ
B17: Croissance du CA | C17: Le cas dégradé retient un CA stable à 0% sur toute la durée du prêt, soit le niveau provisoire 2025 (43 107 M XOF). Justification : (1) La clientèle BTP/infrastructure est cyclique et sensible aux arbitrages budgétaires de l'État. (2) Le secteur est exposé à la concurrence informelle et aux importations asiatiques à bas coût. (3) Les retards de paiement des donneurs d'ordre publics (SODECI, CIE, ISTD) créent des tensions de trésorerie pouvant freiner la capacité de production. (4) Le cas MRAC a démontré qu'un CA stable donne un DSCR de 1,04x — toute contraction de CA entraînerait un passage sous 1,0x. Retenir 0% est donc le scénario de résistance structurelle. | D17: 0.02 | E17: 0.05 | F17: 0.04 | G17: 0.04 | H17: 0 | I17: 0 | J17: 0 | K17: 0 | L17: 0 | M17: 0 | N17: 0 | O17: 0 | P17: 0 | Q17: 0
B18: Poids achats / CA | C18: Le cas dégradé retient 66% (vs 58% client / 63% MRAC). Justification : (1) L'amélioration de la marge brute à 40% en 2024 est un effet déstockage non récurrent — le taux d'achats normatif sur les 4 derniers exercices est de 63-66%. (2) En cas de reprise normale du cycle d'achat avec des matières premières PVC/PEHD importées (volatilité des prix internationaux + risque de change EUR/USD), le poids des achats peut se tendre vers 66-68%. (3) Le dégradé se cale sur la moyenne 2022-2023 qui est le reflet d'une activité normalisée sans effet déstockage. | D18: 0.5801 | E18: 0.5801 | F18: 0.5801 | G18: 0.5801 | H18: 0.5801 | I18: 0.5801 | J18: 0.5801 | K18: 0.66 | L18: 0.66 | M18: 0.66 | N18: 0.66 | O18: 0.66 | P18: 0.66 | Q18: 0.66
B19: Poids frais de personnel / CA | C19: Le cas dégradé retient 13% (vs 10-11% client / 11% MRAC). Justification : (1) Les nouveaux investissements (+57 700 T de capacité) nécessitent des recrutements opérationnels et techniques. (2) Le plan d'expansion annoncé prévoit de porter les effectifs à 3 000 personnes (vs ~600 aujourd'hui), ce qui représente un choc de masse salariale significatif sur la période. (3) En cas de montée progressive des effectifs, le ratio FP/CA peut s'élever à 12-13% avant que le CA additionnel ne compense la charge. | D19: 0.1012 | E19: 0.0996 | F19: 0.0981 | G19: 0.095 | H19: 0.096 | I19: 0.096 | J19: 0.096 | K19: 0.13 | L19: 0.13 | M19: 0.13 | N19: 0.13 | O19: 0.13 | P19: 0.13 | Q19: 0.13
B20: Poids charges externes / CA | C20: Le cas dégradé retient 9% (vs 11% client / 7% MRAC). Justification : (1) Les nouveaux équipements génèrent des coûts de maintenance, garantie et assurance supplémentaires. (2) L'extension géographique (10+ pays) implique des coûts logistiques croissants. (3) Le taux de 9% est un compromis entre le cas MRAC (7%) et le cas client (11%) et reflète la réalité d'une entreprise industrielle en phase d'expansion. | D20: 0.1106 | E20: 0.1099 | F20: 0.1082 | G20: 0.1086 | H20: 0.1094 | I20: 0.1094 | J20: 0.1094 | K20: 0.09 | L20: 0.09 | M20: 0.09 | N20: 0.09 | O20: 0.09 | P20: 0.09 | Q20: 0.09
B21: Marge EBE/CA résultante | C21: Le cas dégradé génère une marge EBE de ~12% (vs ~19% client / ~17% MRAC). Ce niveau correspond à une compression simultanée des marges (achats élevés) et des charges (FP en hausse). C'est le scénario où la montée en charge des investissements ne se traduit pas encore en volume additionnel de CA mais génère déjà des coûts opérationnels. | D21: 0.189 | E21: 0.1911 | F21: 0.1944 | G21: 0.1971 | H21: 0.1953 | I21: 0.1953 | J21: 0.1953 | K21: 0.12 | L21: 0.12 | M21: 0.12 | N21: 0.12 | O21: 0.12 | P21: 0.12 | Q21: 0.12
B22: BFR (jours de CA) | C22: Le cas dégradé retient 265 jours (vs 251j client/MRAC). Justification : (1) En cas de CA stable, les délais clients publics restent structurellement élevés à 180+ jours sans amélioration contractuelle. (2) L'élargissement de l'activité vers de nouveaux marchés sous-régionaux (Burkina, Mali, Niger) peut allonger les délais de recouvrement. (3) 265j = délai clients 190j + stocks 155j − fournisseurs 80j. C'est le niveau observé en 2024 légèrement dégradé pour tenir compte de l'environnement sous-régional post-crise sécuritaire. | D22: 251 | E22: 251 | F22: 251 | G22: 251 | H22: 251 | I22: 251 | J22: 251 | K22: 265 | L22: 265 | M22: 265 | N22: 265 | O22: 260 | P22: 255 | Q22: 250
B23: Capex de maintien annuel (M XOF) | C23: Le cas dégradé retient 700 M XOF/an identique au cas de base. Justification : ce niveau est conservé car il correspond à ~10% du coût du projet (7 000 M XOF), ce qui est le standard industriel pour le maintien d'équipements de production plastique et chimique. Toute réduction en-deçà de ce seuil exposerait la société à une dégradation de la performance technique des unités de production. | D23: 700 | E23: 700 | F23: 700 | G23: 700 | H23: 700 | I23: 700 | J23: 700 | K23: 700 | L23: 700 | M23: 700 | N23: 700 | O23: 700 | P23: 700 | Q23: 700
B24: Amortissements (M XOF) | C24: Le cas dégradé retient les mêmes dotations que le cas de base car elles découlent directement des investissements réalisés (plan d'amortissement fixe — durée 10 ans OHADA). Les dotations augmentent progressivement avec la mise en service des équipements. | D24: 2469 | E24: 3869 | F24: 4102 | G24: 4335 | H24: 4569 | I24: 4569 | J24: 4569 | K24: 2469 | L24: 3869 | M24: 4102 | N24: 4335 | O24: 4569 | P24: 4569 | Q24: 4569
B25: Taux de distribution dividendes | C25: 0% maintenu en cas dégradé. La politique de mise en réserve intégrale observée sur 2022-2024 est un signal fort de discipline financière des actionnaires. Elle doit être maintenue comme condition implicite du financement : tout versement de dividendes en période de tension de trésorerie serait un facteur aggravant. | D25: 0 | E25: 0 | F25: 0 | G25: 0 | H25: 0 | I25: 0 | J25: 0 | K25: 0 | L25: 0 | M25: 0 | N25: 0 | O25: 0 | P25: 0 | Q25: 0
A27: III. PROJECTIONS FINANCIÈRES COMPARÉES (M XOF) — Durée du crédit 2026→2032
D28: 2026 | E28: 2027 | F28: 2028 | G28: 2029 | H28: 2030 | I28: 2031 | J28: 2032 | K28: 2026 | L28: 2027 | M28: 2028 | N28: 2029 | O28: 2030 | P28: 2031 | Q28: 2032
D29: CAS BASE | E29: CAS BASE | F29: CAS BASE | G29: CAS BASE | H29: CAS BASE | I29: CAS BASE | J29: CAS BASE | K29: DÉGRADÉ | L29: DÉGRADÉ | M29: DÉGRADÉ | N29: DÉGRADÉ | O29: DÉGRADÉ | P29: DÉGRADÉ | Q29: DÉGRADÉ
B30: CHIFFRE D'AFFAIRES (M XOF) | D30: 43969.14 | E30: 46167.597 | F30: 48014.301 | G30: 49934.873 | H30: 49934.873 | I30: 49934.873 | J30: 49934.873 | K30: 43107 | L30: 43107 | M30: 43107 | N30: 43107 | O30: 43107 | P30: 43107 | Q30: 43107
B31: Taux EBE/CA (%) | D31: 0.2081 | E31: 0.2104 | F31: 0.2136 | G31: 0.2163 | H31: 0.2145 | I31: 0.2145 | J31: 0.2145 | K31: 0.12 | L31: 0.12 | M31: 0.12 | N31: 0.12 | O31: 0.12 | P31: 0.12 | Q31: 0.12
B32: EXCÉDENT BRUT D'EXPLOITATION | D32: 9149.978 | E32: 9713.6624 | F32: 10255.855 | G32: 10800.913 | H32: 10711.03 | I32: 10711.03 | J32: 10711.03 | K32: 5172.84 | L32: 5172.84 | M32: 5172.84 | N32: 5172.84 | O32: 5172.84 | P32: 5172.84 | Q32: 5172.84
B33: − Dotations amortissements | D33: 2469 | E33: 3869 | F33: 4102 | G33: 4335 | H33: 4569 | I33: 4569 | J33: 4569 | K33: 2469 | L33: 3869 | M33: 4102 | N33: 4335 | O33: 4569 | P33: 4569 | Q33: 4569
B34: + Résultat financier | D34: -1226.25 | E34: -1157.4 | F34: -1013.55 | G34: -869.7 | H34: -725.85 | I34: -582 | J34: -507 | K34: -1226.25 | L34: -1157.4 | M34: -1013.55 | N34: -869.7 | O34: -725.85 | P34: -582 | Q34: -507
B35: RÉSULTAT NET | D35: 4091.046 | E35: 3515.4468 | F35: 3855.2285 | G35: 4197.1598 | H35: 4062.1352 | I35: 4170.0227 | J35: 4226.2727 | K35: 1108.1925 | L35: 109.83 | M35: 42.9675 | N35: -31.86 | O35: -122.01 | P35: 16.38 | Q35: 72.63
B36: MARGE BRUTE D'AUTOFINANCEMENT (MBA) | D36: 6560.046 | E36: 7384.4468 | F36: 7957.2285 | G36: 8532.1598 | H36: 8631.1352 | I36: 8739.0227 | J36: 8795.2727 | K36: 3577.1925 | L36: 3978.83 | M36: 4144.9675 | N36: 4303.14 | O36: 4446.99 | P36: 4585.38 | Q36: 4641.63
B37: BFR (jours de CA) | D37: 251 | E37: 251 | F37: 251 | G37: 251 | H37: 251 | I37: 251 | J37: 251 | K37: 265 | L37: 265 | M37: 265 | N37: 265 | O37: 260 | P37: 255 | Q37: 250
B38: − Variation BFR | D38: 4091.3127 | E38: 1511.8156 | F38: 1269.9251 | G38: 1320.7221 | H38: 0 | I38: 0 | J38: 0 | K38: 5151.863 | L38: 0 | M38: 0 | N38: 0 | O38: -590.50685 | P38: -590.50685 | Q38: -590.50685
B39: CASH FLOW D'EXPLOITATION | D39: 2468.7333 | E39: 5872.6312 | F39: 6687.3034 | G39: 7211.4376 | H39: 8631.1352 | I39: 8739.0227 | J39: 8795.2727 | K39: -1574.6705 | L39: 3978.83 | M39: 4144.9675 | N39: 4303.14 | O39: 5037.4968 | P39: 5175.8868 | Q39: 5232.1368
B40: − Capex de maintien | D40: 700 | E40: 700 | F40: 700 | G40: 700 | H40: 700 | I40: 700 | J40: 700 | K40: 700 | L40: 700 | M40: 700 | N40: 700 | O40: 700 | P40: 700 | Q40: 700
B41: FREE CASH FLOW | D41: 1768.7333 | E41: 5172.6312 | F41: 5987.3034 | G41: 6511.4376 | H41: 7931.1352 | I41: 8039.0227 | J41: 8095.2727 | K41: -2274.6705 | L41: 3278.83 | M41: 3444.9675 | N41: 3603.14 | O41: 4337.4968 | P41: 4475.8868 | Q41: 4532.1368
... B46: Couverture MBA / Annuité | D46: 4.0067467 | E46: 2.8751156 | F46: 3.2819404 | G46: 3.7410268 | H46: 4.0391863 | I46: 4.3848583 | J46: 4.5856479 | K46: 2.1848786 | L46: 1.5491473 | M46: 1.7095822 | N46: 1.8867628 | O46: 2.081096 | P46: 2.3007426 | Q46: 2.4200365
A48: IV. CONCLUSION ANALYTIQUE — CAPACITÉ DE REMBOURSEMENT
...

Sheet Modèle Amélioré
A1: SIPPEC — MODÈLE AMÉLIORÉ | Toutes les projections varient dynamiquement avec les Hypothèses
A2: Vert = repris auto depuis Modèle Original (historique)
A3: Jaune = hypothèse à renseigner dans l'onglet Hypothèses
A4: Bleu = paramètre amortissement capital (saisie implantation)
A5: Rouge = calculé par l'implantation selon taux
A6: Vert clair = résultat calculé dynamiquement
A7: Orange = alerte : ratio sous la norme
B9: M XOF — Exercice 12 mois | C9: 2024 | D9: 2025 | E9: 2026 | F9: 2027 | G9: 2028 | H9: 2029 | I9: 2030 | J9: Total proj. | K9: Amélioration vs Modèle Original
C10: Audité | D10: Audité | E10: Projeté | F10: Projeté | G10: Projeté | H10: Projeté | I10: Projeté
A11: I. CHIFFRE D'AFFAIRES & MARGES ⚡ Amélioration #9 : marge brute normalisée en projection
B12: Hypothèse de croissance CA | C12: - | D12: =(Hypothèses!B9-Hypothèses!B8)/Hypothèses!B8 -> 0.11047149 | E12: =Hypothèses!B10 -> 0.08 | F12: =Hypothèses!B11 -> 0.07 | G12: =Hypothèses!B12 -> 0.05 | H12: =Hypothèses!B12 -> 0.05 | I12: =Hypothèses!B12 -> 0.05 | J12: - | K12: → Liée à Hypothèses!B10-B12
B13: CHIFFRE D'AFFAIRES NET | C13: ='Modèle Original'!C13 -> 38818.224 | D13: ='Modèle Original'!D13 -> 43106.531 | E13: =D13*(1+E12) -> 46555.053 | F13: =E13*(1+F12) -> 49813.907 | G13: =F13*(1+G12) -> 52304.603 | H13: =G13*(1+H12) -> 54919.833 | I13: =H13*(1+I12) -> 57665.824 | J13: =SUM(E13:I13) -> 261259.22
B14: Poids achats / CA ⚡ Normalisé en projection (≠ effet déstockage 2024) | C14: ='Modèle Original'!C14 -> 0.6258 | D14: ='Modèle Original'!D14 -> 0.63 | E14: =Hypothèses!B15 -> 0.63 | F14: =Hypothèses!B15 -> 0.63 | G14: =Hypothèses!B15 -> 0.63 | H14: =Hypothèses!B15 -> 0.63 | I14: =Hypothèses!B15 -> 0.63 | J14: - | K14: Hyp!B15 = taux normalisé. 2024 figé à 62.6% (déstockage)
B15: − Achats & var. stocks de matières | C15: =C13*C14 -> 24292.445 | D15: =D13*D14 -> 27157.115 | E15: =E13*E14 -> 29329.684 | F15: =F13*F14 -> 31382.762 | G15: =G13*G14 -> 32951.9 | H15: =H13*H14 -> 34599.495 | I15: =I13*I14 -> 36329.469 | J15: =SUM(E15:I15) -> 164593.31
B16: Poids frais personnel / CA | C16: =Hypothèses!B16 -> 0.1215 | D16: =Hypothèses!B16 -> 0.1215 | E16: =Hypothèses!B16 -> 0.1215 | F16: =Hypothèses!B16 -> 0.1215 | G16: =Hypothèses!B16 -> 0.1215 | H16: =Hypothèses!B16 -> 0.1215 | I16: =Hypothèses!B16 -> 0.1215 | J16: - | K16: → Hypothèses!B16
B17: − Frais de personnel | C17: =C13*C16 -> 4716.4142 | D17: =D13*D16 -> 5237.4435 | E17: =E13*E16 -> 5656.439 | F17: =F13*F16 -> 6052.3897 | G17: =G13*G16 -> 6355.0092 | H17: =H13*H16 -> 6672.7597 | I17: =I13*I16 -> 7006.3977 | J17: =SUM(E17:I17) -> 31742.995
B18: Poids charges externes / CA | C18: =Hypothèses!B17 -> 0.0725 | D18: =Hypothèses!B17 -> 0.0725 | E18: =Hypothèses!B17 -> 0.0725 | F18: =Hypothèses!B17 -> 0.0725 | G18: =Hypothèses!B17 -> 0.0725 | H18: =Hypothèses!B17 -> 0.0725 | I18: =Hypothèses!B17 -> 0.0725 | J18: - | K18: → Hypothèses!B17
B19: − Charges externes | C19: =C13*C18 -> 2814.3212 | D19: =D13*D18 -> 3125.2235 | E19: =E13*E18 -> 3375.2414 | F19: =F13*F18 -> 3611.5083 | G19: =G13*G18 -> 3792.0837 | H19: =H13*H18 -> 3981.6879 | I19: =I13*I18 -> 4180.7723 | J19: =SUM(E19:I19) -> 18941.293
B20: +/− Autres produits & charges exploitation | C20: 0 | D20: 0 | E20: 0 | F20: 0 | G20: 0 | H20: 0 | I20: 0 | J20: -
B21: Taux EBE/CA ✅ cible ≥ 17% | C21: =IF(C13=0,"-",(C13-C15-C17-C19+C20)/C13) -> 0.1802 | D21: =IF(D13=0,"-",(D13-D15-D17-D19+D20)/D13) -> 0.176 | E21: =IF(E13=0,"-",(E13-E15-E17-E19+E20)/E13) -> 0.176 | F21: =IF(F13=0,"-",(F13-F15-F17-F19+F20)/F13) -> 0.176 | G21: =IF(G13=0,"-",(G13-G15-G17-G19+G20)/G13) -> 0.176 | H21: =IF(H13=0,"-",(H13-H15-H17-H19+H20)/H13) -> 0.176 | I21: =IF(I13=0,"-",(I13-I15-I17-I19+I20)/I13) -> 0.176 | J21: - | K21: Contrôle automatique vs norme 17%
B22: EXCÉDENT BRUT D'EXPLOITATION (EBE) | C22: =C13-C15-C17-C19+C20 -> 6995.044 | D22: =D13-D15-D17-D19+D20 -> 7586.7495 | E22: =E13-E15-E17-E19+E20 -> 8193.6894 | F22: =F13-F15-F17-F19+F20 -> 8767.2477 | G22: =G13-G15-G17-G19+G20 -> 9205.6101 | H22: =H13-H15-H17-H19+H20 -> 9665.8906 | I22: =I13-I15-I17-I19+I20 -> 10149.185 | J22: =SUM(E22:I22) -> 45981.623
A23: II. DOTATIONS AUX AMORTISSEMENTS ⚡ Amélioration #6 : intégration dynamique des nouveaux Capex
B24: Amortissements sur immobilisations existantes (moy.) | C24: =Hypothèses!B20 -> 2368 | D24: =Hypothèses!B20 -> 2368 | E24: =Hypothèses!B20 -> 2368 | F24: =Hypothèses!B20 -> 2368 | G24: =Hypothèses!B20 -> 2368 | H24: =Hypothèses!B20 -> 2368 | I24: =Hypothèses!B20 -> 2368 | J24: - | K24: → Hypothèses!B20 (moy. hist.)
B25: Amort. nouveaux Capex ⚡ Calculé = ΣCapex / Durée (dès mise en service) | C25: 0 | D25: 0 | E25: =IFERROR(Hypothèses!B39/Hypothèses!C39,0)+IFERROR(Hypothèses!B40/Hypothèses!C40,0)+IFERROR(Hypothèses!B41/Hypothèses!C41,0) -> 37.572 | F25: =IFERROR(Hypothèses!B39/Hypothèses!C39,0)+IFERROR(Hypothèses!B40/Hypothèses!C40,0)+IFERROR(Hypothèses!B41/Hypothèses!C41,0) -> 37.572 | G25: =IFERROR(Hypothèses!B39/Hypothèses!C39,0)+IFERROR(Hypothèses!B40/Hypothèses!C40,0)+IFERROR(Hypothèses!B41/Hypothèses!C41,0) -> 37.572 | H25: =IFERROR(Hypothèses!B39/Hypothèses!C39,0)+IFERROR(Hypothèses!B40/Hypothèses!C40,0)+IFERROR(Hypothèses!B41/Hypothèses!C41,0) -> 37.572 | I25: =IFERROR(Hypothèses!B39/Hypothèses!C39,0)+IFERROR(Hypothèses!B40/Hypothèses!C40,0)+IFERROR(Hypothèses!B41/Hypothèses!C41,0) -> 37.572 | J25: - | K25: Somme Capex_i/Durée_i pour chaque ligne
B26: − Dotations totales aux amortissements | C26: =C24+C25 -> 2368 | D26: =D24+D25 -> 2368 | E26: =E24+E25 -> 2405.572 | F26: =F24+F25 -> 2405.572 | G26: =G24+G25 -> 2405.572 | H26: =H24+H25 -> 2405.572 | I26: =I24+I25 -> 2405.572 | J26: =SUM(E26:I26) -> 12027.86
A27: III. RÉSULTAT FINANCIER ⚡ Amélioration #2 : frais financiers calculés sur encours résiduel × taux
B28: Encours dette résiduel (dette existante + nouvelle) | C28: 8261.58 | D28: 8261.58 | E28: =D28+Hypothèses!B29 -> 13261.58 | F28: =MAX(0,E28-Hypothèses!B29/MAX(1,Hypothèses!B30-Hypothèses!B32)) -> 12011.58 | G28: =MAX(0,F28-Hypothèses!B29/MAX(1,Hypothèses!B30-Hypothèses!B32)) -> 10761.58 | H28: =MAX(0,G28-Hypothèses!B29/MAX(1,Hypothèses!B30-Hypothèses!B32)) -> 9511.58 | I28: =MAX(0,H28-Hypothèses!B29/MAX(1,Hypothèses!B30-Hypothèses!B32)) -> 8261.58 | J28: - | K28: Encours = dette N-1 − capital remboursé
B29: FF sur dette existante (moy. historique) | C29: -507 | D29: -507 | E29: -507 | F29: -507 | G29: -507 | H29: -507 | I29: -507 | J29: -
B30: Intérêts nouvelles dettes ⚡ = Encours début × Taux | C30: 0 | D30: 0 | E30: =-E28*Hypothèses!B31 -> -994.6185 | F30: =-F28*Hypothèses!B31 -> -900.8685 | G30: =-G28*Hypothèses!B31 -> -807.1185 | H30: =-H28*Hypothèses!B31 -> -713.3685 | I30: =-I28*Hypothèses!B31 -> -619.6185 | J30: =SUM(E30:I30) -> -4035.5925 | K30: -
B31: + Résultat financier total | C31: =C29+C30 -> -507 | D31: =D29+D30 -> -507 | E31: =E29+E30 -> -1501.6185 | F31: =F29+F30 -> -1407.8685 | G31: =G29+G30 -> -1314.1185 | H31: =H29+H30 -> -1220.3685 | I31: =I29+I30 -> -1126.6185 | J31: -
B32: +/− Autres produits & charges | C32: 0 | D32: 0 | E32: 0 | F32: 0 | G32: 0 | H32: 0 | I32: 0 | J32: -
B33: RÉSULTAT COURANT AVANT IMPÔT | C33: =C22-C26+C31+C32 -> 4120.044 | D33: =D22-D26+D31+D32 -> 4711.7495 | E33: =E22-E26+E31+E32 -> 4286.4989 | F33: =F22-F26+F31+F32 -> 4953.8072 | G33: =G22-G26+G31+G32 -> 5485.9196 | H33: =H22-H26+H31+H32 -> 6039.9501 | I33: =I22-I26+I31+I32 -> 6616.9946 | J33: =SUM(E33:I33) -> 27383.17
B34: − IS (Hypothèses!B34 = 25%) | C34: =IF(C33>0,C33*Hypothèses!B34,0) -> 1030.011 | D34: =IF(D33>0,D33*Hypothèses!B34,0) -> 1177.9374 | E34: =IF(E33>0,E33*Hypothèses!B34,0) -> 1071.6247 | F34: =IF(F33>0,F33*Hypothèses!B34,0) -> 1238.4518 | G34: =IF(G33>0,G33*Hypothèses!B34,0) -> 1371.4799 | H34: =IF(H33>0,H33*Hypothèses!B34,0) -> 1509.9875 | I34: =IF(I33>0,I33*Hypothèses!B34,0) -> 1654.2486 | J34: =SUM(E34:I34) -> 6845.7926 | K34: → Hypothèses!B34
B35: RÉSULTAT NET | C35: =C33-C34 -> 3090.033 | D35: =D33-D34 -> 3533.8121 | E35: =E33-E34 -> 3214.8742 | F35: =F33-F34 -> 3715.3554 | G35: =G33-G34 -> 4114.4397 | H35: =H33-H34 -> 4529.9625 | I35: =I33-I34 -> 4962.7459 | J35: =SUM(E35:I35) -> 20537.378
B36: MARGE BRUTE D'AUTOFINANCEMENT (MBA) | C36: =C35+C26 -> 5458.033 | D36: =D35+D26 -> 5901.8121 | E36: =E35+E26 -> 5620.4462 | F36: =F35+F26 -> 6120.9274 | G36: =G35+G26 -> 6520.0117 | H36: =H35+H26 -> 6935.5345 | I36: =I35+I26 -> 7368.3179 | J36: =SUM(E36:I36) -> 32565.238
A37: IV. BFR ENDOGÈNE ⚡ Amélioration #3 : BFR calculé par délais (clients + stocks − fournis.) × CA/365
B38: Délai clients (j) — depuis Hypothèses | C38: 181 | D38: 153 | E38: =Hypothèses!B23 -> 175 | F38: =Hypothèses!B23 -> 175 | G38: =Hypothèses!B23 -> 175 | H38: =Hypothèses!B23 -> 175 | I38: =Hypothèses!B23 -> 175 | J38: - | K38: → Hypothèses!B23
B39: Délai stocks (j) | C39: 137 | D39: 177 | E39: =Hypothèses!B24 -> 140 | F39: =Hypothèses!B24 -> 140 | G39: =Hypothèses!B24 -> 140 | H39: =Hypothèses!B24 -> 140 | I39: =Hypothèses!B24 -> 140 | J39: - | K39: → Hypothèses!B24
B40: Délai fournisseurs (j d'achats) | C40: 133 | D40: 153 | E40: =Hypothèses!B25 -> 130 | F40: =Hypothèses!B25 -> 130 | G40: =Hypothèses!B25 -> 130 | H40: =Hypothèses!B25 -> 130 | I40: =Hypothèses!B25 -> 130 | J40: - | K40: → Hypothèses!B25
B41: BFR en jours de CA ⚡ = Clients + Stocks − Fournisseurs | C41: =C38+C39-C40 -> 185 | D41: =D38+D39-D40 -> 177 | E41: =E38+E39-E40 -> 185 | F41: =F38+F39-F40 -> 185 | G41: =G38+G39-G40 -> 185 | H41: =H38+H39-H40 -> 185 | I41: =I38+I39-I40 -> 185 | J41: - | K41: Calculé dynamiquement (≠ jours fixes)
...

Sheet Hypothèses
A1: SIPPEC — HYPOTHÈSES DE MODÉLISATION | À renseigner avant projection
A2: 🔵 Cellule bleue = INPUT à saisir (hardcodé)
A3: 🟡 Fond jaune = hypothèse critique à valider avec le chargé d'affaires
A4: 🟢 Fond vert = calculé automatiquement (ne pas modifier)
A5: 🔴 Fond orange = paramètre lié au financement sollicité
A7: A. ACTIVITÉ — Hypothèses de croissance
A8: CA base 2024 (M XOF) — exercice audité | B8: 38818.224 | C8: Source: États financiers audités 31/12/2024
A9: CA provisoire 2025 (M XOF) | B9: 43106.531 | C9: Source: Chiffres provisoires client
A10: Taux de croissance CA 2026 | B10: 0.08 | C10: Hypothèse : tendance 2024-2025 +7-11% / à valider CA
A11: Taux de croissance CA 2027 | B11: 0.07
A12: Taux de croissance CA 2028-2030 (taux terminal) | B12: 0.05 | C12: Hypothèse conservatrice long terme
A14: B. MARGES & CHARGES — Poids en % du CA
A15: Achats & var. stocks / CA | B15: 0.63 | C15: 2024 : 63% (vs 75% en 2023) — effet déstockage à normaliser
A16: Frais de personnel / CA | B16: 0.1215 | C16: 2024 : 12,15% — stable sur la période
A17: Charges externes / CA | B17: 0.0725 | C17: 2024 : 7,25% — stable
A18: Autres produits & charges exploit. / CA | B18: 0 | C18: À renseigner selon données client
A19: Taux d'EBE/CA cible (contrôle) | B19: 0.17 | C19: Calculé : doit converger vers 17% historique
A20: Dotations amort. corporels moy. (M XOF) | B20: 2368 | C20: Moyenne des 3 derniers exercices
A22: C. BFR — Hypothèses de délais
A23: Délai clients (jours de CA) | B23: 175 | C23: 2024 : 181j / 2025P : 153j — retenir 175j prudent
A24: Délai stocks (jours de CA) | B24: 140 | C24: 2024 : 137j — légère hausse projetée
A25: Délai fournisseurs (jours d'achats) | B25: 130 | C25: 2024 : 133j — maintien
A26: BFR en jours de CA (contrôle) | B26: 246 | C26: Référence 2024 auditée
A28: D. FINANCEMENT SOLLICITÉ
A29: Montant du crédit sollicité (M XOF) | B29: 5000 | C29: À renseigner
A30: Durée (années) | B30: 5 | C30: À renseigner
A31: Taux d'intérêt annuel | B31: 0.075 | C31: À calculer par l'implantation
A32: Différé en capital (années) | B32: 1 | C32: À renseigner selon modalités
A33: Date de mise en place | B33: 2026
A34: Taux IS applicable | B34: 0.25 | C34: Taux OHADA CI : 25%
A35: Taux de distribution des dividendes | B35: 0 | C35: 0% : politique de mise en réserve observée
A37: E. CAPEX LIÉS À L'INVESTISSEMENT
A38: Description du Capex | B38: Montant (M XOF) | C38: Durée amort. (années)
A39: Unité de production peinture vinylique | B39: 375.72 | C39: 10
A40: Renforcement capacité PEHD 250 | C40: 10
A41: Autres Capex (à préciser) | C41: 10

Sheet Projections Cash Flow
A1: SIPPEC — PROJECTIONS CASH FLOW | M XOF | 2024 Audité / 2025P / 2026-2030 Projeté
A2: Vert foncé = Données historiques auditées | B2: Bleu clair = Données provisoires 2025 | C2: Blanc = Projections modélisées | D2: Gris = Soldes / totaux intermédiaires
A3: M XOF / Exercice (12 mois) | B3: 2024 | C3: 2025 | D3: 2026 | E3: 2027 | F3: 2028 | G3: 2029 | H3: 2030
A4: Nature | B4: Audité | C4: Provisoire | D4: Projeté | E4: Projeté | F4: Projeté | G4: Projeté | H4: Projeté
A5: I. COMPTE DE RÉSULTAT PRÉVISIONNEL
A6: Chiffre d'Affaires (CA) | B6: 38818.224 | C6: 43106.531 | D6: 46555.053 | E6: 49813.907 | F6: 52304.603 | G6: 54919.833 | H6: 57665.824
A7: − Achats & var. stocks (% CA) | B7: 24292.445 | C7: 26976.067 | D7: 30726.335 | E7: 33375.318 | F7: 35044.084 | G7: 36796.288 | H7: 38636.102
A8: VALEUR AJOUTÉE | B8: 14525.779 | C8: 16130.464 | D8: 15828.718 | E8: 16438.589 | F8: 17260.519 | G8: 18123.545 | H8: 19029.722
A9: − Frais de personnel | B9: 4716.4142 | C9: 5237.4435 | D9: 5656.439 | E9: 6052.3897 | F9: 6355.0092 | G9: 6672.7597 | H9: 7006.3977
A10: − Charges externes | B10: 2814.3212 | C10: 3125.2235 | D10: 3375.2414 | E10: 3611.5083 | F10: 3792.0837 | G10: 3981.6879 | H10: 4180.7723
A11: EXCÉDENT BRUT D'EXPLOITATION (EBE) | B11: 6995.044 | C11: 7767.7969 | D11: 6797.0378 | E11: 6774.6914 | F11: 7113.426 | G11: 7469.0972 | H11: 7842.5521
A12: Taux EBE/CA (%) | B12: 0.1802 | C12: 0.1802 | D12: 0.146 | E12: 0.136 | F12: 0.136 | G12: 0.136 | H12: 0.136
A13: − Dotations aux amortissements | B13: 2368 | C13: 2368 | D13: 2368 | E13: 2368 | F13: 2368 | G13: 2368 | H13: 2368
A14: RÉSULTAT D'EXPLOITATION (EBIT) | B14: 4627.044 | C14: 5399.7969 | D14: 4429.0378 | E14: 4406.6914 | F14: 4745.426 | G14: 5101.0972 | H14: 5474.5521
A15: + Résultat financier (moy. hist.) | B15: -507 | C15: -507 | D15: -507 | E15: -507 | F15: -507 | G15: -507 | H15: -507
A16: RÉSULTAT COURANT AVANT IMPÔT | B16: 4120.044 | C16: 4892.7969 | D16: 3922.0378 | E16: 3899.6914 | F16: 4238.426 | G16: 4594.0972 | H16: 4967.5521
A17: − Impôt sur les sociétés (25%) | B17: 1030.011 | C17: 1223.1992 | D17: 980.50945 | E17: 974.92285 | F17: 1059.6065 | G17: 1148.5243 | H17: 1241.888
... A21: MBA/CA (%) | B21: 0.14060491 | C21: 0.14006225 | D21: 0.11404838 | E21: 0.10625082 | F21: 0.1060484 | G21: 0.10585562 | H21: 0.10567202
A23: II. BFR & CASH FLOW D'EXPLOITATION
A24: BFR en jours de CA | B24: 246 | C24: 251 | D24: 246 | E24: 240 | F24: 240 | G24: 235 | H24: 230
A25: BFR en montant (M XOF) | B25: 26162.419 | C25: 29643.121 | D25: 31376.831 | E25: 32754.35 | F25: 34392.067 | G25: 35359.344 | H25: 36337.369
A26: Variation du BFR (− = besoin additionnel) | B26: 0 | C26: 3480.7019 | D26: 1733.7092 | E26: 1377.5194 | F26: 1637.7175 | G26: 967.2769 | H26: 978.02442
A27: CASH FLOW D'EXPLOITATION (CFE = MBA − ΔBFR) | B27: 5458.033 | C27: 2556.8958 | D27: 3575.8191 | E27: 3915.2491 | F27: 3909.102 | G27: 4846.296 | H27: 5115.6397
A28: CFE / CA (%) | B28: 0.14060491 | C28: 0.059315741 | D28: 0.076808399 | E28: 0.078597512 | F28: 0.074737246 | G28: 0.088243095 | H28: 0.08871181
A30: III. SERVICE DE LA DETTE (à paramétrer dans Hypothèses)
A31: ⚠ Les annuités ci-dessous sont des PLACEHOLDERS — à remplacer par le tableau d'amortissement réel
A32: − Intérêts sur nouvelle dette | D32: 300 | E32: 300 | F32: 300 | G32: 300 | H32: 300
A33: − Remboursement en capital | D33: 700 | E33: 700 | F33: 700 | G33: 700 | H33: 700
A34: ANNUITÉ TOTALE (Capital + Intérêts) | D34: 1000 | E34: 1000 | F34: 1000 | G34: 1000 | H34: 1000
A36: IV. CASH FLOW DISPONIBLE APRÈS SERVICE DE LA DETTE (CFADS)
A37: CFADS = CFE − Annuité totale | B37: 5458.033 | C37: 2556.8958 | D37: 2575.8191 | E37: 2915.2491 | F37: 2909.102 | G37: 3846.296 | H37: 4115.6397
A38: DSCR — Debt Service Coverage Ratio (CFE / Annuité) | D38: 3.5758191 | E38: 3.9152491 | F38: 3.909102 | G38: 4.846296 | H38: 5.1156397
A39: Leverage (Endt total / EBE) — référence 2024 | B39: 1.181122
A40: Couverture MBA / Annuité (norme ≥ 1.2x) | D40: 5.3095284 | E40: 5.2927685 | F40: 5.5468195 | G40: 5.8135729 | H40: 6.0936641
A42: V. TRÉSORERIE NETTE PROJETÉE
A43: Trésorerie nette cumulée (M XOF) | B43: -3101.52 | C43: -544.62419 | D43: 2031.1949 | E43: 4946.4441 | F43: 7855.546 | G43: 11701.842 | H43: 15817.482
A44: Trésorerie / CA (%) | B44: -0.079898555 | C44: -0.012634378 | D44: 0.043629956 | E44: 0.099298456 | F44: 0.15018843 | G44: 0.21307133 | H44: 0.2742956

Sheet Pistes d'Amélioration
A1: PISTES D'AMÉLIORATION DU MODÈLE — Recommandations analytiques
A2: # | B2: Axe d'amélioration | C2: Description & Justification | D2: Action recommandée | E2: Priorité
A3: 1 | B3: Tableau d'amortissement dédié | C3: Le modèle actuel utilise des annuités fixes (placeholders). Un tableau d'amortissement réel doit être construit avec : montant, taux, durée, différé, type (linéaire/dégressif). Chaque ligne de dette (existante + nouvelle) doit figurer séparément. | D3: Créer un onglet 'Tableau Amortissement' avec amortissement détaillé par tranche de dette. Lier les annuités à cet onglet. | E3: 🔴 CRITIQUE
A4: 2 | B4: Traitement du Résultat Financier | C4: Le modèle projette le résultat financier à sa moyenne historique (-507 M XOF). C'est insuffisant : les frais financiers doivent être calculés dynamiquement sur l'encours de dette résiduel × taux. Sans cela, le DSCR est biaisé. | D4: Lier les frais financiers au tableau d'amortissement. Calculer FF = encours début de période × taux. | E4: 🔴 CRITIQUE
A5: 3 | B5: Modélisation du BFR endogène | C5: Le BFR est projeté en jours de CA fixes. Or, le BFR dépend des délais clients, fournisseurs et stocks qui peuvent évoluer. Le modèle devrait permettre de faire varier ces délais pour mesurer l'impact sur le cash flow. | D5: Remplacer le BFR en jours fixe par un calcul : BFR = (Délai clients + Délai stocks − Délai fournis.) × CA/365. Lier aux hypothèses. | E5: 🟠 HAUTE
A6: 4 | B6: Scénarios de stress | C6: Le modèle ne propose qu'un scénario central. Pour une décision de crédit, il est indispensable d'avoir un scénario pessimiste (CA −10%, marges compressées, BFR dégradé) pour tester la résistance du DSCR. | D6: Ajouter un onglet 'Stress Test' avec 3 scénarios : Base / Pessimiste (−10% CA) / Optimiste (+10% CA). Calculer le DSCR dans chaque cas. | E6: 🟠 HAUTE
A7: 5 | B7: Correction erreur division par zéro | C7: L'erreur DIV/0 sur 'Trésorerie/CA' provient d'années sans CA projeté. Le modèle original ne protège pas les formules contre les dénominateurs nuls. | D7: Encapsuler toutes les divisions dans IF(dénominateur=0,"-",numérateur/dénominateur). | E7: 🟡 NORMALE
A8: 6 | B8: Intégration des Capex amortissables | C8: Les nouveaux investissements génèrent des dotations supplémentaires qui réduisent le résultat imposable mais augmentent la MBA. Le modèle doit intégrer dynamiquement les nouvelles dotations selon la durée d'amortissement. | D8: Créer un tableau de suivi Capex avec : année de mise en service, montant, durée, dotation annuelle. Sommer avec les amortissements existants. | E8: 🟡 NORMALE
A9: 7 | B9: Traitement du CCA bloqué | C9: Le CCA bloqué à 25 057 M XOF est une ressource structurelle critique. Le modèle ne modélise pas le risque de déblocage partiel, qui réduirait instantanément les capitaux permanents et dégraderait le gearing. | D9: Ajouter une ligne 'Variation CCA bloqué' dans le cash flow. Tester en scénario de stress l'impact d'un déblocage partiel de 20%. | E9: 🟡 NORMALE
A10: 8 | B10: Indicateur de couverture par l'EBE | C10: Le DSCR calculé sur le CFE est le bon indicateur mais il doit être complété par EBE/Annuité (ratio de couverture bancaire standard). L'EBE est moins volatile que le CFE car non affecté par la variation du BFR. | D10: Ajouter la ligne EBE/Annuité en parallèle du DSCR. Norme minimale : 1.2x. | E10: 🟡 NORMALE
A11: 9 | B11: Normalisation de la marge brute | C11: La marge brute 2024 à 40% est atypique (effet déstockage). Le modèle doit utiliser une marge normalisée (moyenne 3 ans pondérée) comme base de projection pour éviter de surestimer le cash flow disponible. | D11: Utiliser un taux d'achats/CA de 65-67% en projection (vs 63% en 2024). Annoter l'hypothèse retenue. | E11: 🟡 NORMALE
A12: 10 | B12: Horizon de projection | C12: L'horizon 2030 (6 ans) est adapté pour un crédit MLT standard de 5-7 ans. Pour des financements plus longs, l'horizon doit couvrir la durée du crédit + 1 an après dernière échéance. | D12: Paramétrer l'horizon de projection dynamiquement selon la durée saisie dans les hypothèses. | E12: 🟢 FAIBLE
