Workbook

Sheet CONFIG
A1: Chemin Access | B1: S:\DRR_NOTIFICATION_DE_CREDIT\DEAL FLOW\OUTIL_DEAL_FLOW.accbd
A2: Feuille mise a jour
A3: Derniere connexion
A4: Statut | B4: Non connecte

Sheet 🏠 Accueil
B2: SUIVI DES SUSPENS | SGCI / DRC
B3: Connecte a la base Access | Actualisation automatique
B6: >> ACTUALISER DEPUIS ACCESS << | G6: =CONFIG!B4 -> Non connecte
B8: INDICATEURS CLES (mis a jour automatiquement)
B9: Dossiers en suspens (Access) | I9: =COUNTIF('📋 Suspens'!H:H,"En cours") -> 0
B10: Clotures ce mois | I10: =COUNTIFS('📋 Suspens'!H:H,"Cloture",'📋 Suspens'!O:O,TEXT(TODAY(),"MMMM YYYY")) -> 0
B11: En cours depuis plus de 30 jours | I11: =COUNTIFS('📋 Suspens'!H:H,"En cours",'📋 Suspens'!I:I,"<="&TODAY()-30) -> 0
B12: Nouveaux ce mois | I12: =COUNTIFS('📋 Suspens'!O:O,TEXT(TODAY(),"MMMM YYYY"),'📋 Suspens'!H:H,"En cours") -> 0
B13: Duree moyenne en cours (jours) | I13: =IFERROR(AVERAGEIF('📋 Suspens'!H:H,"En cours",'📋 Suspens'!I:I),"-") -> -
B14: Total dossiers importes depuis Access | I14: =COUNTA('📥 Donnees Access'!A:A)-2 -> 1
B16: =IFERROR("Derniere actualisation : "&TEXT(CONFIG!C3,"DD/MM/YYYY HH:MM"),"Non actualise") -> Derniere actualisation : 30/12/1899 00:00

Sheet 📥 Donnees Access
A1: DONNEES IMPORTEES DEPUIS ACCESS | Table [data base] - En suspens uniquement
A2: IDSG | B2: RCT | C2: CLIENT | D2: ETAT | E2: ANALYSTE | F2: DEMANDE | G2: DATE DE RECEPTION | H2: DATE D ATTRIBUTION | I2: DATE DE PRISE EN CHARGE | J2: DATE D ENVOIE AU SIGNATAIRE | K2: SIGNATAIRE | L2: DATE DE SIGNATURE | M2: ENVOIE MARCHE 1 | N2: RETOUR MARCHE 1 | O2: ENVOIE MARCHE 2 | P2: RETOUR MARCHE 2 | Q2: SECTEUR | R2: NOTE | S2: LAD | T2: MXOF | U2: DECISION | V2: DELAI ANALYSTE | W2: DELAI TOTAL
A3: Cliquer sur le bouton ACTUALISER dans l'onglet Accueil pour importer les donnees Access

Sheet 📋 Suspens
A1: SUIVI DES SUSPENS | SGCI (alimente depuis Access)
A2: N° | B2: IDSG (Access) | C2: RCT | D2: CLIENT | E2: ANALYSTE (Access) | F2: ETAT (Access) | G2: DATE RECEPTION | H2: STATUT SUIVI | I2: DUREE (jours) | J2: RAISON PRINCIPALE | K2: RAISON 2 | L2: RAISON 3 | M2: COMMENTAIRES DRC | N2: DEMANDE (Access) | O2: MOIS | P2: ANNEE
A3: =IF(B3<>"",ROW()-2,"") | I3: =IF(AND(G3<>"",H3="En cours"),TODAY()-G3,IF(AND(G3<>"",H3="Cloture"),TODAY()-G3,"")) | O3: =IF(G3<>"",TEXT(G3,"MMMM YYYY"),"") | P3: =IF(G3<>"",YEAR(G3),"")
A4: =IF(B4<>"",ROW()-2,"") | I4: =IF(AND(G4<>"",H4="En cours"),TODAY()-G4,IF(AND(G4<>"",H4="Cloture"),TODAY()-G4,"")) | O4: =IF(G4<>"",TEXT(G4,"MMMM YYYY"),"") | P4: =IF(G4<>"",YEAR(G4),"")
A5: =IF(B5<>"",ROW()-2,"") | I5: =IF(AND(G5<>"",H5="En cours"),TODAY()-G5,IF(AND(G5<>"",H5="Cloture"),TODAY()-G5,"")) | O5: =IF(G5<>"",TEXT(G5,"MMMM YYYY"),"") | P5: =IF(G5<>"",YEAR(G5),"")
A6: =IF(B6<>"",ROW()-2,"") | I6: =IF(AND(G6<>"",H6="En cours"),TODAY()-G6,IF(AND(G6<>"",H6="Cloture"),TODAY()-G6,"")) | O6: =IF(G6<>"",TEXT(G6,"MMMM YYYY"),"") | P6: =IF(G6<>"",YEAR(G6),"")
A7: =IF(B7<>"",ROW()-2,"") | I7: =IF(AND(G7<>"",H7="En cours"),TODAY()-G7,IF(AND(G7<>"",H7="Cloture"),TODAY()-G7,"")) | O7: =IF(G7<>"",TEXT(G7,"MMMM YYYY"),"") | P7: =IF(G7<>"",YEAR(G7),"")
A8: =IF(B8<>"",ROW()-2,"") | I8: =IF(AND(G8<>"",H8="En cours"),TODAY()-G8,IF(AND(G8<>"",H8="Cloture"),TODAY()-G8,"")) | O8: =IF(G8<>"",TEXT(G8,"MMMM YYYY"),"") | P8: =IF(G8<>"",YEAR(G8),"")
A9: =IF(B9<>"",ROW()-2,"") | I9: =IF(AND(G9<>"",H9="En cours"),TODAY()-G9,IF(AND(G9<>"",H9="Cloture"),TODAY()-G9,"")) | O9: =IF(G9<>"",TEXT(G9,"MMMM YYYY"),"") | P9: =IF(G9<>"",YEAR(G9),"")
A10: =IF(B10<>"",ROW()-2,"") | I10: =IF(AND(G10<>"",H10="En cours"),TODAY()-G10,IF(AND(G10<>"",H10="Cloture"),TODAY()-G10,"")) | O10: =IF(G10<>"",TEXT(G10,"MMMM YYYY"),"") | P10: =IF(G10<>"",YEAR(G10),"")
A11: =IF(B11<>"",ROW()-2,"") | I11: =IF(AND(G11<>"",H11="En cours"),TODAY()-G11,IF(AND(G11<>"",H11="Cloture"),TODAY()-G11,"")) | O11: =IF(G11<>"",TEXT(G11,"MMMM YYYY"),"") | P11: =IF(G11<>"",YEAR(G11),"")
A12: =IF(B12<>"",ROW()-2,"") | I12: =IF(AND(G12<>"",H12="En cours"),TODAY()-G12,IF(AND(G12<>"",H12="Cloture"),TODAY()-G12,"")) | O12: =IF(G12<>"",TEXT(G12,"MMMM YYYY"),"") | P12: =IF(G12<>"",YEAR(G12),"")
A13: =IF(B13<>"",ROW()-2,"") | I13: =IF(AND(G13<>"",H13="En cours"),TODAY()-G13,IF(AND(G13<>"",H13="Cloture"),TODAY()-G13,"")) | O13: =IF(G13<>"",TEXT(G13,"MMMM YYYY"),"") | P13: =IF(G13<>"",YEAR(G13),"")
A14: =IF(B14<>"",ROW()-2,"") | I14: =IF(AND(G14<>"",H14="En cours"),TODAY()-G14,IF(AND(G14<>"",H14="Cloture"),TODAY()-G14,"")) | O14: =IF(G14<>"",TEXT(G14,"MMMM YYYY"),"") | P14: =IF(G14<>"",YEAR(G14),"")
... A202: =IF(B202<>"",ROW()-2,"") | I202: =IF(AND(G202<>"",H202="En cours"),TODAY()-G202,IF(AND(G202<>"",H202="Cloture"),TODAY()-G202,"")) | O202: =IF(G202<>"",TEXT(G202,"MMMM YYYY"),"") | P202: =IF(G202<>"",YEAR(G202),"")

Sheet 📊 Statistiques
A1: STATISTIQUES DES SUSPENS | SGCI
A3: SUSPENS PAR RAISON
A4: RAISON DU SUSPENS | B4: TOTAL | C4: EN COURS | D4: CLOTURE | E4: EN ATTENTE | F4: DUREE MOY (j) | G4: % DU TOTAL
A5: Absence de CREDAPP | B5: =COUNTIF('📋 Suspens'!J:J,A5)+COUNTIF('📋 Suspens'!K:K,A5)+COUNTIF('📋 Suspens'!L:L,A5) -> 0 | C5: =COUNTIFS('📋 Suspens'!J:J,A5,'📋 Suspens'!H:H,"En cours")+COUNTIFS('📋 Suspens'!K:K,A5,'📋 Suspens'!H:H,"En cours")+COUNTIFS('📋 Suspens'!L:L,A5,'📋 Suspens'!H:H,"En cours") -> 0 | D5: =COUNTIFS('📋 Suspens'!J:J,A5,'📋 Suspens'!H:H,"Cloture")+COUNTIFS('📋 Suspens'!K:K,A5,'📋 Suspens'!H:H,"Cloture")+COUNTIFS('📋 Suspens'!L:L,A5,'📋 Suspens'!H:H,"Cloture") -> 0 | E5: =COUNTIFS('📋 Suspens'!J:J,A5,'📋 Suspens'!H:H,"En attente")+COUNTIFS('📋 Suspens'!K:K,A5,'📋 Suspens'!H:H,"En attente")+COUNTIFS('📋 Suspens'!L:L,A5,'📋 Suspens'!H:H,"En attente") -> 0 | F5: =IFERROR(AVERAGEIFS('📋 Suspens'!I:I,'📋 Suspens'!J:J,A5,'📋 Suspens'!H:H,"Cloture"),"") | G5: =IFERROR(B5/SUM($B$5:$B$31),0) -> 0
A6: Absence de notice financiere | B6: =COUNTIF('📋 Suspens'!J:J,A6)+COUNTIF('📋 Suspens'!K:K,A6)+COUNTIF('📋 Suspens'!L:L,A6) -> 0 | C6: =COUNTIFS('📋 Suspens'!J:J,A6,'📋 Suspens'!H:H,"En cours")+COUNTIFS('📋 Suspens'!K:K,A6,'📋 Suspens'!H:H,"En cours")+COUNTIFS('📋 Suspens'!L:L,A6,'📋 Suspens'!H:H,"En cours") -> 0 | D6: =COUNTIFS('📋 Suspens'!J:J,A6,'📋 Suspens'!H:H,"Cloture")+COUNTIFS('📋 Suspens'!K:K,A6,'📋 Suspens'!H:H,"Cloture")+COUNTIFS('📋 Suspens'!L:L,A6,'📋 Suspens'!H:H,"Cloture") -> 0 | E6: =COUNTIFS('📋 Suspens'!J:J,A6,'📋 Suspens'!H:H,"En attente")+COUNTIFS('📋 Suspens'!K:K,A6,'📋 Suspens'!H:H,"En attente")+COUNTIFS('📋 Suspens'!L:L,A6,'📋 Suspens'!H:H,"En attente") -> 0 | F6: =IFERROR(AVERAGEIFS('📋 Suspens'!I:I,'📋 Suspens'!J:J,A6,'📋 Suspens'!H:H,"Cloture"),"") | G6: =IFERROR(B6/SUM($B$5:$B$31),0) -> 0
A7: Absence de page de signature | B7: =COUNTIF('📋 Suspens'!J:J,A7)+COUNTIF('📋 Suspens'!K:K,A7)+COUNTIF('📋 Suspens'!L:L,A7) -> 0 | C7: =COUNTIFS('📋 Suspens'!J:J,A7,'📋 Suspens'!H:H,"En cours")+COUNTIFS('📋 Suspens'!K:K,A7,'📋 Suspens'!H:H,"En cours")+COUNTIFS('📋 Suspens'!L:L,A7,'📋 Suspens'!H:H,"En cours") -> 0 | D7: =COUNTIFS('📋 Suspens'!J:J,A7,'📋 Suspens'!H:H,"Cloture")+COUNTIFS('📋 Suspens'!K:K,A7,'📋 Suspens'!H:H,"Cloture")+COUNTIFS('📋 Suspens'!L:L,A7,'📋 Suspens'!H:H,"Cloture") -> 0 | E7: =COUNTIFS('📋 Suspens'!J:J,A7,'📋 Suspens'!H:H,"En attente")+COUNTIFS('📋 Suspens'!K:K,A7,'📋 Suspens'!H:H,"En attente")+COUNTIFS('📋 Suspens'!L:L,A7,'📋 Suspens'!H:H,"En attente") -> 0 | F7: =IFERROR(AVERAGEIFS('📋 Suspens'!I:I,'📋 Suspens'!J:J,A7,'📋 Suspens'!H:H,"Cloture"),"") | G7: =IFERROR(B7/SUM($B$5:$B$31),0) -> 0
A8: Absence de rapport CAC ou derogation CRO | B8: =COUNTIF('📋 Suspens'!J:J,A8)+COUNTIF('📋 Suspens'!K:K,A8)+COUNTIF('📋 Suspens'!L:L,A8) -> 0 | C8: =COUNTIFS('📋 Suspens'!J:J,A8,'📋 Suspens'!H:H,"En cours")+COUNTIFS('📋 Suspens'!K:K,A8,'📋 Suspens'!H:H,"En cours")+COUNTIFS('📋 Suspens'!L:L,A8,'📋 Suspens'!H:H,"En cours") -> 0 | D8: =COUNTIFS('📋 Suspens'!J:J,A8,'📋 Suspens'!H:H,"Cloture")+COUNTIFS('📋 Suspens'!K:K,A8,'📋 Suspens'!H:H,"Cloture")+COUNTIFS('📋 Suspens'!L:L,A8,'📋 Suspens'!H:H,"Cloture") -> 0 | E8: =COUNTIFS('📋 Suspens'!J:J,A8,'📋 Suspens'!H:H,"En attente")+COUNTIFS('📋 Suspens'!K:K,A8,'📋 Suspens'!H:H,"En attente")+COUNTIFS('📋 Suspens'!L:L,A8,'📋 Suspens'!H:H,"En attente") -> 0 | F8: =IFERROR(AVERAGEIFS('📋 Suspens'!I:I,'📋 Suspens'!J:J,A8,'📋 Suspens'!H:H,"Cloture"),"") | G8: =IFERROR(B8/SUM($B$5:$B$31),0) -> 0
A9: Absence de fiche KYC | B9: =COUNTIF('📋 Suspens'!J:J,A9)+COUNTIF('📋 Suspens'!K:K,A9)+COUNTIF('📋 Suspens'!L:L,A9) -> 0 | C9: =COUNTIFS('📋 Suspens'!J:J,A9,'📋 Suspens'!H:H,"En cours")+COUNTIFS('📋 Suspens'!K:K,A9,'📋 Suspens'!H:H,"En cours")+COUNTIFS('📋 Suspens'!L:L,A9,'📋 Suspens'!H:H,"En cours") -> 0 | D9: =COUNTIFS('📋 Suspens'!J:J,A9,'📋 Suspens'!H:H,"Cloture")+COUNTIFS('📋 Suspens'!K:K,A9,'📋 Suspens'!H:H,"Cloture")+COUNTIFS('📋 Suspens'!L:L,A9,'📋 Suspens'!H:H,"Cloture") -> 0 | E9: =COUNTIFS('📋 Suspens'!J:J,A9,'📋 Suspens'!H:H,"En attente")+COUNTIFS('📋 Suspens'!K:K,A9,'📋 Suspens'!H:H,"En attente")+COUNTIFS('📋 Suspens'!L:L,A9,'📋 Suspens'!H:H,"En attente") -> 0 | F9: =IFERROR(AVERAGEIFS('📋 Suspens'!I:I,'📋 Suspens'!J:J,A9,'📋 Suspens'!H:H,"Cloture"),"") | G9: =IFERROR(B9/SUM($B$5:$B$31),0) -> 0
A10: Absence des fiches RBO | B10: =COUNTIF('📋 Suspens'!J:J,A10)+COUNTIF('📋 Suspens'!K:K,A10)+COUNTIF('📋 Suspens'!L:L,A10) -> 0 | C10: =COUNTIFS('📋 Suspens'!J:J,A10,'📋 Suspens'!H:H,"En cours")+COUNTIFS('📋 Suspens'!K:K,A10,'📋 Suspens'!H:H,"En cours")+COUNTIFS('📋 Suspens'!L:L,A10,'📋 Suspens'!H:H,"En cours") -> 0 | D10: =COUNTIFS('📋 Suspens'!J:J,A10,'📋 Suspens'!H:H,"Cloture")+COUNTIFS('📋 Suspens'!K:K,A10,'📋 Suspens'!H:H,"Cloture")+COUNTIFS('📋 Suspens'!L:L,A10,'📋 Suspens'!H:H,"Cloture") -> 0 | E10: =COUNTIFS('📋 Suspens'!J:J,A10,'📋 Suspens'!H:H,"En attente")+COUNTIFS('📋 Suspens'!K:K,A10,'📋 Suspens'!H:H,"En attente")+COUNTIFS('📋 Suspens'!L:L,A10,'📋 Suspens'!H:H,"En attente") -> 0 | F10: =IFERROR(AVERAGEIFS('📋 Suspens'!I:I,'📋 Suspens'!J:J,A10,'📋 Suspens'!H:H,"Cloture"),"") | G10: =IFERROR(B10/SUM($B$5:$B$31),0) -> 0
A11: Absence de la fiche CLEO | B11: =COUNTIF('📋 Suspens'!J:J,A11)+COUNTIF('📋 Suspens'!K:K,A11)+COUNTIF('📋 Suspens'!L:L,A11) -> 0 | C11: =COUNTIFS('📋 Suspens'!J:J,A11,'📋 Suspens'!H:H,"En cours")+COUNTIFS('📋 Suspens'!K:K,A11,'📋 Suspens'!H:H,"En cours")+COUNTIFS('📋 Suspens'!L:L,A11,'📋 Suspens'!H:H,"En cours") -> 0 | D11: =COUNTIFS('📋 Suspens'!J:J,A11,'📋 Suspens'!H:H,"Cloture")+COUNTIFS('📋 Suspens'!K:K,A11,'📋 Suspens'!H:H,"Cloture")+COUNTIFS('📋 Suspens'!L:L,A11,'📋 Suspens'!H:H,"Cloture") -> 0 | E11: =COUNTIFS('📋 Suspens'!J:J,A11,'📋 Suspens'!H:H,"En attente")+COUNTIFS('📋 Suspens'!K:K,A11,'📋 Suspens'!H:H,"En attente")+COUNTIFS('📋 Suspens'!L:L,A11,'📋 Suspens'!H:H,"En attente") -> 0 | F11: =IFERROR(AVERAGEIFS('📋 Suspens'!I:I,'📋 Suspens'!J:J,A11,'📋 Suspens'!H:H,"Cloture"),"") | G11: =IFERROR(B11/SUM($B$5:$B$31),0) -> 0
A12: Absence de la GL du PCRU | B12: =COUNTIF('📋 Suspens'!J:J,A12)+COUNTIF('📋 Suspens'!K:K,A12)+COUNTIF('📋 Suspens'!L:L,A12) -> 0 | C12: =COUNTIFS('📋 Suspens'!J:J,A12,'📋 Suspens'!H:H,"En cours")+COUNTIFS('📋 Suspens'!K:K,A12,'📋 Suspens'!H:H,"En cours")+COUNTIFS('📋 Suspens'!L:L,A12,'📋 Suspens'!H:H,"En cours") -> 0 | D12: =COUNTIFS('📋 Suspens'!J:J,A12,'📋 Suspens'!H:H,"Cloture")+COUNTIFS('📋 Suspens'!K:K,A12,'📋 Suspens'!H:H,"Cloture")+COUNTIFS('📋 Suspens'!L:L,A12,'📋 Suspens'!H:H,"Cloture") -> 0 | E12: =COUNTIFS('📋 Suspens'!J:J,A12,'📋 Suspens'!H:H,"En attente")+COUNTIFS('📋 Suspens'!K:K,A12,'📋 Suspens'!H:H,"En attente")+COUNTIFS('📋 Suspens'!L:L,A12,'📋 Suspens'!H:H,"En attente") -> 0 | F12: =IFERROR(AVERAGEIFS('📋 Suspens'!I:I,'📋 Suspens'!J:J,A12,'📋 Suspens'!H:H,"Cloture"),"") | G12: =IFERROR(B12/SUM($B$5:$B$31),0) -> 0
A13: Absence de projet de note NOVA | B13: =COUNTIF('📋 Suspens'!J:J,A13)+COUNTIF('📋 Suspens'!K:K,A13)+COUNTIF('📋 Suspens'!L:L,A13) -> 0 | C13: =COUNTIFS('📋 Suspens'!J:J,A13,'📋 Suspens'!H:H,"En cours")+COUNTIFS('📋 Suspens'!K:K,A13,'📋 Suspens'!H:H,"En cours")+COUNTIFS('📋 Suspens'!L:L,A13,'📋 Suspens'!H:H,"En cours") -> 0 | D13: =COUNTIFS('📋 Suspens'!J:J,A13,'📋 Suspens'!H:H,"Cloture")+COUNTIFS('📋 Suspens'!K:K,A13,'📋 Suspens'!H:H,"Cloture")+COUNTIFS('📋 Suspens'!L:L,A13,'📋 Suspens'!H:H,"Cloture") -> 0 | E13: =COUNTIFS('📋 Suspens'!J:J,A13,'📋 Suspens'!H:H,"En attente")+COUNTIFS('📋 Suspens'!K:K,A13,'📋 Suspens'!H:H,"En attente")+COUNTIFS('📋 Suspens'!L:L,A13,'📋 Suspens'!H:H,"En attente") -> 0 | F13: =IFERROR(AVERAGEIFS('📋 Suspens'!I:I,'📋 Suspens'!J:J,A13,'📋 Suspens'!H:H,"Cloture"),"") | G13: =IFERROR(B13/SUM($B$5:$B$31),0) -> 0
A14: Absence de la fiche RSE | B14: =COUNTIF('📋 Suspens'!J:J,A14)+COUNTIF('📋 Suspens'!K:K,A14)+COUNTIF('📋 Suspens'!L:L,A14) -> 0 | C14: =COUNTIFS('📋 Suspens'!J:J,A14,'📋 Suspens'!H:H,"En cours")+COUNTIFS('📋 Suspens'!K:K,A14,'📋 Suspens'!H:H,"En cours")+COUNTIFS('📋 Suspens'!L:L,A14,'📋 Suspens'!H:H,"En cours") -> 0 | D14: =COUNTIFS('📋 Suspens'!J:J,A14,'📋 Suspens'!H:H,"Cloture")+COUNTIFS('📋 Suspens'!K:K,A14,'📋 Suspens'!H:H,"Cloture")+COUNTIFS('📋 Suspens'!L:L,A14,'📋 Suspens'!H:H,"Cloture") -> 0 | E14: =COUNTIFS('📋 Suspens'!J:J,A14,'📋 Suspens'!H:H,"En attente")+COUNTIFS('📋 Suspens'!K:K,A14,'📋 Suspens'!H:H,"En attente")+COUNTIFS('📋 Suspens'!L:L,A14,'📋 Suspens'!H:H,"En attente") -> 0 | F14: =IFERROR(AVERAGEIFS('📋 Suspens'!I:I,'📋 Suspens'!J:J,A14,'📋 Suspens'!H:H,"Cloture"),"") | G14: =IFERROR(B14/SUM($B$5:$B$31),0) -> 0
A15: Absence de quitus fiscal | B15: =COUNTIF('📋 Suspens'!J:J,A15)+COUNTIF('📋 Suspens'!K:K,A15)+COUNTIF('📋 Suspens'!L:L,A15) -> 0 | C15: =COUNTIFS('📋 Suspens'!J:J,A15,'📋 Suspens'!H:H,"En cours")+COUNTIFS('📋 Suspens'!K:K,A15,'📋 Suspens'!H:H,"En cours")+COUNTIFS('📋 Suspens'!L:L,A15,'📋 Suspens'!H:H,"En cours") -> 0 | D15: =COUNTIFS('📋 Suspens'!J:J,A15,'📋 Suspens'!H:H,"Cloture")+COUNTIFS('📋 Suspens'!K:K,A15,'📋 Suspens'!H:H,"Cloture")+COUNTIFS('📋 Suspens'!L:L,A15,'📋 Suspens'!H:H,"Cloture") -> 0 | E15: =COUNTIFS('📋 Suspens'!J:J,A15,'📋 Suspens'!H:H,"En attente")+COUNTIFS('📋 Suspens'!K:K,A15,'📋 Suspens'!H:H,"En attente")+COUNTIFS('📋 Suspens'!L:L,A15,'📋 Suspens'!H:H,"En attente") -> 0 | F15: =IFERROR(AVERAGEIFS('📋 Suspens'!I:I,'📋 Suspens'!J:J,A15,'📋 Suspens'!H:H,"Cloture"),"") | G15: =IFERROR(B15/SUM($B$5:$B$31),0) -> 0
A16: Absence de fiche BIC | B16: =COUNTIF('📋 Suspens'!J:J,A16)+COUNTIF('📋 Suspens'!K:K,A16)+COUNTIF('📋 Suspens'!L:L,A16) -> 0 | C16: =COUNTIFS('📋 Suspens'!J:J,A16,'📋 Suspens'!H:H,"En cours")+COUNTIFS('📋 Suspens'!K:K,A16,'📋 Suspens'!H:H,"En cours")+COUNTIFS('📋 Suspens'!L:L,A16,'📋 Suspens'!H:H,"En cours") -> 0 | D16: =COUNTIFS('📋 Suspens'!J:J,A16,'📋 Suspens'!H:H,"Cloture")+COUNTIFS('📋 Suspens'!K:K,A16,'📋 Suspens'!H:H,"Cloture")+COUNTIFS('📋 Suspens'!L:L,A16,'📋 Suspens'!H:H,"Cloture") -> 0 | E16: =COUNTIFS('📋 Suspens'!J:J,A16,'📋 Suspens'!H:H,"En attente")+COUNTIFS('📋 Suspens'!K:K,A16,'📋 Suspens'!H:H,"En attente")+COUNTIFS('📋 Suspens'!L:L,A16,'📋 Suspens'!H:H,"En attente") -> 0 | F16: =IFERROR(AVERAGEIFS('📋 Suspens'!I:I,'📋 Suspens'!J:J,A16,'📋 Suspens'!H:H,"Cloture"),"") | G16: =IFERROR(B16/SUM($B$5:$B$31),0) -> 0
... A31: Autre | B31: =COUNTIF('📋 Suspens'!J:J,A31)+COUNTIF('📋 Suspens'!K:K,A31)+COUNTIF('📋 Suspens'!L:L,A31) -> 0 | C31: =COUNTIFS('📋 Suspens'!J:J,A31,'📋 Suspens'!H:H,"En cours")+COUNTIFS('📋 Suspens'!K:K,A31,'📋 Suspens'!H:H,"En cours")+COUNTIFS('📋 Suspens'!L:L,A31,'📋 Suspens'!H:H,"En cours") -> 0 | D31: =COUNTIFS('📋 Suspens'!J:J,A31,'📋 Suspens'!H:H,"Cloture")+COUNTIFS('📋 Suspens'!K:K,A31,'📋 Suspens'!H:H,"Cloture")+COUNTIFS('📋 Suspens'!L:L,A31,'📋 Suspens'!H:H,"Cloture") -> 0 | E31: =COUNTIFS('📋 Suspens'!J:J,A31,'📋 Suspens'!H:H,"En attente")+COUNTIFS('📋 Suspens'!K:K,A31,'📋 Suspens'!H:H,"En attente")+COUNTIFS('📋 Suspens'!L:L,A31,'📋 Suspens'!H:H,"En attente") -> 0 | F31: =IFERROR(AVERAGEIFS('📋 Suspens'!I:I,'📋 Suspens'!J:J,A31,'📋 Suspens'!H:H,"Cloture"),"") | G31: =IFERROR(B31/SUM($B$5:$B$31),0) -> 0
A32: TOTAL | B32: =SUM(B5:B31) -> 0 | C32: =SUM(C5:C31) -> 0 | D32: =SUM(D5:D31) -> 0 | E32: =SUM(E5:E31) -> 0
A34: SUSPENS PAR ANALYSTE
A35: ANALYSTE | B35: EN COURS | C35: CLOTURE | D35: EN ATTENTE | E35: TOTAL | F35: DUREE MOY (j) | G35: DOSSIERS > 30j
A36: =IF('⚙️ Parametres'!C2<>"",'⚙️ Parametres'!C2,"") -> ANALYSTES (mis a jour depuis Access) | B36: =IF(A36<>"",COUNTIFS('📋 Suspens'!E:E,A36,'📋 Suspens'!H:H,"En cours"),"") -> 0 | C36: =IF(A36<>"",COUNTIFS('📋 Suspens'!E:E,A36,'📋 Suspens'!H:H,"Cloture"),"") -> 0 | D36: =IF(A36<>"",COUNTIFS('📋 Suspens'!E:E,A36,'📋 Suspens'!H:H,"En attente"),"") -> 0 | E36: =IF(A36<>"",COUNTIF('📋 Suspens'!E:E,A36),"") -> 0 | F36: =IFERROR(AVERAGEIFS('📋 Suspens'!I:I,'📋 Suspens'!E:E,A36,'📋 Suspens'!H:H,"Cloture"),"") | G36: =IF(A36<>"",COUNTIFS('📋 Suspens'!E:E,A36,'📋 Suspens'!H:H,"En cours",'📋 Suspens'!I:I,">30"),"") -> 0
A37: =IF('⚙️ Parametres'!C3<>"",'⚙️ Parametres'!C3,"") | B37: =IF(A37<>"",COUNTIFS('📋 Suspens'!E:E,A37,'📋 Suspens'!H:H,"En cours"),"") | C37: =IF(A37<>"",COUNTIFS('📋 Suspens'!E:E,A37,'📋 Suspens'!H:H,"Cloture"),"") | D37: =IF(A37<>"",COUNTIFS('📋 Suspens'!E:E,A37,'📋 Suspens'!H:H,"En attente"),"") | E37: =IF(A37<>"",COUNTIF('📋 Suspens'!E:E,A37),"") | F37: =IFERROR(AVERAGEIFS('📋 Suspens'!I:I,'📋 Suspens'!E:E,A37,'📋 Suspens'!H:H,"Cloture"),"") | G37: =IF(A37<>"",COUNTIFS('📋 Suspens'!E:E,A37,'📋 Suspens'!H:H,"En cours",'📋 Suspens'!I:I,">30"),"")
A38: =IF('⚙️ Parametres'!C4<>"",'⚙️ Parametres'!C4,"") | B38: =IF(A38<>"",COUNTIFS('📋 Suspens'!E:E,A38,'📋 Suspens'!H:H,"En cours"),"") | C38: =IF(A38<>"",COUNTIFS('📋 Suspens'!E:E,A38,'📋 Suspens'!H:H,"Cloture"),"") | D38: =IF(A38<>"",COUNTIFS('📋 Suspens'!E:E,A38,'📋 Suspens'!H:H,"En attente"),"") | E38: =IF(A38<>"",COUNTIF('📋 Suspens'!E:E,A38),"") | F38: =IFERROR(AVERAGEIFS('📋 Suspens'!I:I,'📋 Suspens'!E:E,A38,'📋 Suspens'!H:H,"Cloture"),"") | G38: =IF(A38<>"",COUNTIFS('📋 Suspens'!E:E,A38,'📋 Suspens'!H:H,"En cours",'📋 Suspens'!I:I,">30"),"")
A39: =IF('⚙️ Parametres'!C5<>"",'⚙️ Parametres'!C5,"") | B39: =IF(A39<>"",COUNTIFS('📋 Suspens'!E:E,A39,'📋 Suspens'!H:H,"En cours"),"") | C39: =IF(A39<>"",COUNTIFS('📋 Suspens'!E:E,A39,'📋 Suspens'!H:H,"Cloture"),"") | D39: =IF(A39<>"",COUNTIFS('📋 Suspens'!E:E,A39,'📋 Suspens'!H:H,"En attente"),"") | E39: =IF(A39<>"",COUNTIF('📋 Suspens'!E:E,A39),"") | F39: =IFERROR(AVERAGEIFS('📋 Suspens'!I:I,'📋 Suspens'!E:E,A39,'📋 Suspens'!H:H,"Cloture"),"") | G39: =IF(A39<>"",COUNTIFS('📋 Suspens'!E:E,A39,'📋 Suspens'!H:H,"En cours",'📋 Suspens'!I:I,">30"),"")
A40: =IF('⚙️ Parametres'!C6<>"",'⚙️ Parametres'!C6,"") | B40: =IF(A40<>"",COUNTIFS('📋 Suspens'!E:E,A40,'📋 Suspens'!H:H,"En cours"),"") | C40: =IF(A40<>"",COUNTIFS('📋 Suspens'!E:E,A40,'📋 Suspens'!H:H,"Cloture"),"") | D40: =IF(A40<>"",COUNTIFS('📋 Suspens'!E:E,A40,'📋 Suspens'!H:H,"En attente"),"") | E40: =IF(A40<>"",COUNTIF('📋 Suspens'!E:E,A40),"") | F40: =IFERROR(AVERAGEIFS('📋 Suspens'!I:I,'📋 Suspens'!E:E,A40,'📋 Suspens'!H:H,"Cloture"),"") | G40: =IF(A40<>"",COUNTIFS('📋 Suspens'!E:E,A40,'📋 Suspens'!H:H,"En cours",'📋 Suspens'!I:I,">30"),"")
A41: =IF('⚙️ Parametres'!C7<>"",'⚙️ Parametres'!C7,"") | B41: =IF(A41<>"",COUNTIFS('📋 Suspens'!E:E,A41,'📋 Suspens'!H:H,"En cours"),"") | C41: =IF(A41<>"",COUNTIFS('📋 Suspens'!E:E,A41,'📋 Suspens'!H:H,"Cloture"),"") | D41: =IF(A41<>"",COUNTIFS('📋 Suspens'!E:E,A41,'📋 Suspens'!H:H,"En attente"),"") | E41: =IF(A41<>"",COUNTIF('📋 Suspens'!E:E,A41),"") | F41: =IFERROR(AVERAGEIFS('📋 Suspens'!I:I,'📋 Suspens'!E:E,A41,'📋 Suspens'!H:H,"Cloture"),"") | G41: =IF(A41<>"",COUNTIFS('📋 Suspens'!E:E,A41,'📋 Suspens'!H:H,"En cours",'📋 Suspens'!I:I,">30"),"")
A42: =IF('⚙️ Parametres'!C8<>"",'⚙️ Parametres'!C8,"") | B42: =IF(A42<>"",COUNTIFS('📋 Suspens'!E:E,A42,'📋 Suspens'!H:H,"En cours"),"") | C42: =IF(A42<>"",COUNTIFS('📋 Suspens'!E:E,A42,'📋 Suspens'!H:H,"Cloture"),"") | D42: =IF(A42<>"",COUNTIFS('📋 Suspens'!E:E,A42,'📋 Suspens'!H:H,"En attente"),"") | E42: =IF(A42<>"",COUNTIF('📋 Suspens'!E:E,A42),"") | F42: =IFERROR(AVERAGEIFS('📋 Suspens'!I:I,'📋 Suspens'!E:E,A42,'📋 Suspens'!H:H,"Cloture"),"") | G42: =IF(A42<>"",COUNTIFS('📋 Suspens'!E:E,A42,'📋 Suspens'!H:H,"En cours",'📋 Suspens'!I:I,">30"),"")
A43: =IF('⚙️ Parametres'!C9<>"",'⚙️ Parametres'!C9,"") | B43: =IF(A43<>"",COUNTIFS('📋 Suspens'!E:E,A43,'📋 Suspens'!H:H,"En cours"),"") | C43: =IF(A43<>"",COUNTIFS('📋 Suspens'!E:E,A43,'📋 Suspens'!H:H,"Cloture"),"") | D43: =IF(A43<>"",COUNTIFS('📋 Suspens'!E:E,A43,'📋 Suspens'!H:H,"En attente"),"") | E43: =IF(A43<>"",COUNTIF('📋 Suspens'!E:E,A43),"") | F43: =IFERROR(AVERAGEIFS('📋 Suspens'!I:I,'📋 Suspens'!E:E,A43,'📋 Suspens'!H:H,"Cloture"),"") | G43: =IF(A43<>"",COUNTIFS('📋 Suspens'!E:E,A43,'📋 Suspens'!H:H,"En cours",'📋 Suspens'!I:I,">30"),"")
A44: =IF('⚙️ Parametres'!C10<>"",'⚙️ Parametres'!C10,"") | B44: =IF(A44<>"",COUNTIFS('📋 Suspens'!E:E,A44,'📋 Suspens'!H:H,"En cours"),"") | C44: =IF(A44<>"",COUNTIFS('📋 Suspens'!E:E,A44,'📋 Suspens'!H:H,"Cloture"),"") | D44: =IF(A44<>"",COUNTIFS('📋 Suspens'!E:E,A44,'📋 Suspens'!H:H,"En attente"),"") | E44: =IF(A44<>"",COUNTIF('📋 Suspens'!E:E,A44),"") | F44: =IFERROR(AVERAGEIFS('📋 Suspens'!I:I,'📋 Suspens'!E:E,A44,'📋 Suspens'!H:H,"Cloture"),"") | G44: =IF(A44<>"",COUNTIFS('📋 Suspens'!E:E,A44,'📋 Suspens'!H:H,"En cours",'📋 Suspens'!I:I,">30"),"")
A45: =IF('⚙️ Parametres'!C11<>"",'⚙️ Parametres'!C11,"") | B45: =IF(A45<>"",COUNTIFS('📋 Suspens'!E:E,A45,'📋 Suspens'!H:H,"En cours"),"") | C45: =IF(A45<>"",COUNTIFS('📋 Suspens'!E:E,A45,'📋 Suspens'!H:H,"Cloture"),"") | D45: =IF(A45<>"",COUNTIFS('📋 Suspens'!E:E,A45,'📋 Suspens'!H:H,"En attente"),"") | E45: =IF(A45<>"",COUNTIF('📋 Suspens'!E:E,A45),"") | F45: =IFERROR(AVERAGEIFS('📋 Suspens'!I:I,'📋 Suspens'!E:E,A45,'📋 Suspens'!H:H,"Cloture"),"") | G45: =IF(A45<>"",COUNTIFS('📋 Suspens'!E:E,A45,'📋 Suspens'!H:H,"En cours",'📋 Suspens'!I:I,">30"),"")
A46: =IF('⚙️ Parametres'!C12<>"",'⚙️ Parametres'!C12,"") | B46: =IF(A46<>"",COUNTIFS('📋 Suspens'!E:E,A46,'📋 Suspens'!H:H,"En cours"),"") | C46: =IF(A46<>"",COUNTIFS('📋 Suspens'!E:E,A46,'📋 Suspens'!H:H,"Cloture"),"") | D46: =IF(A46<>"",COUNTIFS('📋 Suspens'!E:E,A46,'📋 Suspens'!H:H,"En attente"),"") | E46: =IF(A46<>"",COUNTIF('📋 Suspens'!E:E,A46),"") | F46: =IFERROR(AVERAGEIFS('📋 Suspens'!I:I,'📋 Suspens'!E:E,A46,'📋 Suspens'!H:H,"Cloture"),"") | G46: =IF(A46<>"",COUNTIFS('📋 Suspens'!E:E,A46,'📋 Suspens'!H:H,"En cours",'📋 Suspens'!I:I,">30"),"")
A47: =IF('⚙️ Parametres'!C13<>"",'⚙️ Parametres'!C13,"") | B47: =IF(A47<>"",COUNTIFS('📋 Suspens'!E:E,A47,'📋 Suspens'!H:H,"En cours"),"") | C47: =IF(A47<>"",COUNTIFS('📋 Suspens'!E:E,A47,'📋 Suspens'!H:H,"Cloture"),"") | D47: =IF(A47<>"",COUNTIFS('📋 Suspens'!E:E,A47,'📋 Suspens'!H:H,"En attente"),"") | E47: =IF(A47<>"",COUNTIF('📋 Suspens'!E:E,A47),"") | F47: =IFERROR(AVERAGEIFS('📋 Suspens'!I:I,'📋 Suspens'!E:E,A47,'📋 Suspens'!H:H,"Cloture"),"") | G47: =IF(A47<>"",COUNTIFS('📋 Suspens'!E:E,A47,'📋 Suspens'!H:H,"En cours",'📋 Suspens'!I:I,">30"),"")
... A85: =IF('⚙️ Parametres'!C51<>"",'⚙️ Parametres'!C51,"") | B85: =IF(A85<>"",COUNTIFS('📋 Suspens'!E:E,A85,'📋 Suspens'!H:H,"En cours"),"") | C85: =IF(A85<>"",COUNTIFS('📋 Suspens'!E:E,A85,'📋 Suspens'!H:H,"Cloture"),"") | D85: =IF(A85<>"",COUNTIFS('📋 Suspens'!E:E,A85,'📋 Suspens'!H:H,"En attente"),"") | E85: =IF(A85<>"",COUNTIF('📋 Suspens'!E:E,A85),"") | F85: =IFERROR(AVERAGEIFS('📋 Suspens'!I:I,'📋 Suspens'!E:E,A85,'📋 Suspens'!H:H,"Cloture"),"") | G85: =IF(A85<>"",COUNTIFS('📋 Suspens'!E:E,A85,'📋 Suspens'!H:H,"En cours",'📋 Suspens'!I:I,">30"),"")
A86: * Liste des analystes mise a jour automatiquement depuis Access a chaque actualisation

Sheet 📈 Graphiques
A1: TABLEAU DE BORD GRAPHIQUE | SGCI
A3: SUSPENS PAR RAISON (Top 10 par volume) | P3: REPARTITION PAR STATUT
A23: SUSPENS EN COURS PAR ANALYSTE | P23: EVOLUTION MENSUELLE DES SUSPENS
A44: RAISON (Top 10) | K44: NB | N44: STATUT | R44: NB
A45: =IFERROR(INDEX('📊 Statistiques'!$A$5:$A$31,MATCH(LARGE('📊 Statistiques'!$B$5:$B$31,1),'📊 Statistiques'!$B$5:$B$31,0)),"") -> Absence de CREDAPP | K45: =IFERROR(LARGE('📊 Statistiques'!$B$5:$B$31,1),0) -> 0 | N45: En cours | R45: =COUNTIF('📋 Suspens'!H:H,"En cours") -> 0
A46: =IFERROR(INDEX('📊 Statistiques'!$A$5:$A$31,MATCH(LARGE('📊 Statistiques'!$B$5:$B$31,2),'📊 Statistiques'!$B$5:$B$31,0)),"") -> Absence de CREDAPP | K46: =IFERROR(LARGE('📊 Statistiques'!$B$5:$B$31,2),0) -> 0 | N46: Cloture | R46: =COUNTIF('📋 Suspens'!H:H,"Cloture") -> 0
A47: =IFERROR(INDEX('📊 Statistiques'!$A$5:$A$31,MATCH(LARGE('📊 Statistiques'!$B$5:$B$31,3),'📊 Statistiques'!$B$5:$B$31,0)),"") -> Absence de CREDAPP | K47: =IFERROR(LARGE('📊 Statistiques'!$B$5:$B$31,3),0) -> 0 | N47: En attente | R47: =COUNTIF('📋 Suspens'!H:H,"En attente") -> 0
A48: =IFERROR(INDEX('📊 Statistiques'!$A$5:$A$31,MATCH(LARGE('📊 Statistiques'!$B$5:$B$31,4),'📊 Statistiques'!$B$5:$B$31,0)),"") -> Absence de CREDAPP | K48: =IFERROR(LARGE('📊 Statistiques'!$B$5:$B$31,4),0) -> 0
A49: =IFERROR(INDEX('📊 Statistiques'!$A$5:$A$31,MATCH(LARGE('📊 Statistiques'!$B$5:$B$31,5),'📊 Statistiques'!$B$5:$B$31,0)),"") -> Absence de CREDAPP | K49: =IFERROR(LARGE('📊 Statistiques'!$B$5:$B$31,5),0) -> 0
A50: =IFERROR(INDEX('📊 Statistiques'!$A$5:$A$31,MATCH(LARGE('📊 Statistiques'!$B$5:$B$31,6),'📊 Statistiques'!$B$5:$B$31,0)),"") -> Absence de CREDAPP | K50: =IFERROR(LARGE('📊 Statistiques'!$B$5:$B$31,6),0) -> 0
A51: =IFERROR(INDEX('📊 Statistiques'!$A$5:$A$31,MATCH(LARGE('📊 Statistiques'!$B$5:$B$31,7),'📊 Statistiques'!$B$5:$B$31,0)),"") -> Absence de CREDAPP | K51: =IFERROR(LARGE('📊 Statistiques'!$B$5:$B$31,7),0) -> 0
A52: =IFERROR(INDEX('📊 Statistiques'!$A$5:$A$31,MATCH(LARGE('📊 Statistiques'!$B$5:$B$31,8),'📊 Statistiques'!$B$5:$B$31,0)),"") -> Absence de CREDAPP | K52: =IFERROR(LARGE('📊 Statistiques'!$B$5:$B$31,8),0) -> 0
A53: =IFERROR(INDEX('📊 Statistiques'!$A$5:$A$31,MATCH(LARGE('📊 Statistiques'!$B$5:$B$31,9),'📊 Statistiques'!$B$5:$B$31,0)),"") -> Absence de CREDAPP | K53: =IFERROR(LARGE('📊 Statistiques'!$B$5:$B$31,9),0) -> 0
A54: =IFERROR(INDEX('📊 Statistiques'!$A$5:$A$31,MATCH(LARGE('📊 Statistiques'!$B$5:$B$31,10),'📊 Statistiques'!$B$5:$B$31,0)),"") -> Absence de CREDAPP | K54: =IFERROR(LARGE('📊 Statistiques'!$B$5:$B$31,10),0) -> 0

Sheet 📅 Mensuel
A1: SUIVI MENSUEL DES SUSPENS | SGCI (2026)
A3: INDICATEUR | B3: January 2026 | C3: February 2026 | D3: March 2026 | E3: April 2026 | F3: May 2026 | G3: June 2026 | H3: July 2026 | I3: August 2026 | J3: September 2026 | K3: October 2026 | L3: November 2026 | M3: December 2026
A4: Nouveaux suspens recus | B4: =COUNTIFS('📋 Suspens'!O:O,"January 2026") -> 0 | C4: =COUNTIFS('📋 Suspens'!O:O,"February 2026") -> 0 | D4: =COUNTIFS('📋 Suspens'!O:O,"March 2026") -> 0 | E4: =COUNTIFS('📋 Suspens'!O:O,"April 2026") -> 0 | F4: =COUNTIFS('📋 Suspens'!O:O,"May 2026") -> 0 | G4: =COUNTIFS('📋 Suspens'!O:O,"June 2026") -> 0 | H4: =COUNTIFS('📋 Suspens'!O:O,"July 2026") -> 0 | I4: =COUNTIFS('📋 Suspens'!O:O,"August 2026") -> 0 | J4: =COUNTIFS('📋 Suspens'!O:O,"September 2026") -> 0 | K4: =COUNTIFS('📋 Suspens'!O:O,"October 2026") -> 0 | L4: =COUNTIFS('📋 Suspens'!O:O,"November 2026") -> 0 | M4: =COUNTIFS('📋 Suspens'!O:O,"December 2026") -> 0
A5: Suspens clotures | B5: =COUNTIFS('📋 Suspens'!O:O,"January 2026",'📋 Suspens'!H:H,"Cloture") -> 0 | C5: =COUNTIFS('📋 Suspens'!O:O,"February 2026",'📋 Suspens'!H:H,"Cloture") -> 0 | D5: =COUNTIFS('📋 Suspens'!O:O,"March 2026",'📋 Suspens'!H:H,"Cloture") -> 0 | E5: =COUNTIFS('📋 Suspens'!O:O,"April 2026",'📋 Suspens'!H:H,"Cloture") -> 0 | F5: =COUNTIFS('📋 Suspens'!O:O,"May 2026",'📋 Suspens'!H:H,"Cloture") -> 0 | G5: =COUNTIFS('📋 Suspens'!O:O,"June 2026",'📋 Suspens'!H:H,"Cloture") -> 0 | H5: =COUNTIFS('📋 Suspens'!O:O,"July 2026",'📋 Suspens'!H:H,"Cloture") -> 0 | I5: =COUNTIFS('📋 Suspens'!O:O,"August 2026",'📋 Suspens'!H:H,"Cloture") -> 0 | J5: =COUNTIFS('📋 Suspens'!O:O,"September 2026",'📋 Suspens'!H:H,"Cloture") -> 0 | K5: =COUNTIFS('📋 Suspens'!O:O,"October 2026",'📋 Suspens'!H:H,"Cloture") -> 0 | L5: =COUNTIFS('📋 Suspens'!O:O,"November 2026",'📋 Suspens'!H:H,"Cloture") -> 0 | M5: =COUNTIFS('📋 Suspens'!O:O,"December 2026",'📋 Suspens'!H:H,"Cloture") -> 0
A6: Duree moy. clotures (j) | B6: =IFERROR(AVERAGEIFS('📋 Suspens'!I:I,'📋 Suspens'!O:O,"January 2026",'📋 Suspens'!H:H,"Cloture"),"") | C6: =IFERROR(AVERAGEIFS('📋 Suspens'!I:I,'📋 Suspens'!O:O,"February 2026",'📋 Suspens'!H:H,"Cloture"),"") | D6: =IFERROR(AVERAGEIFS('📋 Suspens'!I:I,'📋 Suspens'!O:O,"March 2026",'📋 Suspens'!H:H,"Cloture"),"") | E6: =IFERROR(AVERAGEIFS('📋 Suspens'!I:I,'📋 Suspens'!O:O,"April 2026",'📋 Suspens'!H:H,"Cloture"),"") | F6: =IFERROR(AVERAGEIFS('📋 Suspens'!I:I,'📋 Suspens'!O:O,"May 2026",'📋 Suspens'!H:H,"Cloture"),"") | G6: =IFERROR(AVERAGEIFS('📋 Suspens'!I:I,'📋 Suspens'!O:O,"June 2026",'📋 Suspens'!H:H,"Cloture"),"") | H6: =IFERROR(AVERAGEIFS('📋 Suspens'!I:I,'📋 Suspens'!O:O,"July 2026",'📋 Suspens'!H:H,"Cloture"),"") | I6: =IFERROR(AVERAGEIFS('📋 Suspens'!I:I,'📋 Suspens'!O:O,"August 2026",'📋 Suspens'!H:H,"Cloture"),"") | J6: =IFERROR(AVERAGEIFS('📋 Suspens'!I:I,'📋 Suspens'!O:O,"September 2026",'📋 Suspens'!H:H,"Cloture"),"") | K6: =IFERROR(AVERAGEIFS('📋 Suspens'!I:I,'📋 Suspens'!O:O,"October 2026",'📋 Suspens'!H:H,"Cloture"),"") | L6: =IFERROR(AVERAGEIFS('📋 Suspens'!I:I,'📋 Suspens'!O:O,"November 2026",'📋 Suspens'!H:H,"Cloture"),"") | M6: =IFERROR(AVERAGEIFS('📋 Suspens'!I:I,'📋 Suspens'!O:O,"December 2026",'📋 Suspens'!H:H,"Cloture"),"")
A7: Suspens > 30j en cours | B7: =COUNTIFS('📋 Suspens'!O:O,"January 2026",'📋 Suspens'!H:H,"En cours",'📋 Suspens'!I:I,">30") -> 0 | C7: =COUNTIFS('📋 Suspens'!O:O,"February 2026",'📋 Suspens'!H:H,"En cours",'📋 Suspens'!I:I,">30") -> 0 | D7: =COUNTIFS('📋 Suspens'!O:O,"March 2026",'📋 Suspens'!H:H,"En cours",'📋 Suspens'!I:I,">30") -> 0 | E7: =COUNTIFS('📋 Suspens'!O:O,"April 2026",'📋 Suspens'!H:H,"En cours",'📋 Suspens'!I:I,">30") -> 0 | F7: =COUNTIFS('📋 Suspens'!O:O,"May 2026",'📋 Suspens'!H:H,"En cours",'📋 Suspens'!I:I,">30") -> 0 | G7: =COUNTIFS('📋 Suspens'!O:O,"June 2026",'📋 Suspens'!H:H,"En cours",'📋 Suspens'!I:I,">30") -> 0 | H7: =COUNTIFS('📋 Suspens'!O:O,"July 2026",'📋 Suspens'!H:H,"En cours",'📋 Suspens'!I:I,">30") -> 0 | I7: =COUNTIFS('📋 Suspens'!O:O,"August 2026",'📋 Suspens'!H:H,"En cours",'📋 Suspens'!I:I,">30") -> 0 | J7: =COUNTIFS('📋 Suspens'!O:O,"September 2026",'📋 Suspens'!H:H,"En cours",'📋 Suspens'!I:I,">30") -> 0 | K7: =COUNTIFS('📋 Suspens'!O:O,"October 2026",'📋 Suspens'!H:H,"En cours",'📋 Suspens'!I:I,">30") -> 0 | L7: =COUNTIFS('📋 Suspens'!O:O,"November 2026",'📋 Suspens'!H:H,"En cours",'📋 Suspens'!I:I,">30") -> 0 | M7: =COUNTIFS('📋 Suspens'!O:O,"December 2026",'📋 Suspens'!H:H,"En cours",'📋 Suspens'!I:I,">30") -> 0
A10: NOUVEAUX SUSPENS PAR ANALYSTE ET PAR MOIS
A11: ANALYSTE | B11: January 2026 | C11: February 2026 | D11: March 2026 | E11: April 2026 | F11: May 2026 | G11: June 2026 | H11: July 2026 | I11: August 2026 | J11: September 2026 | K11: October 2026 | L11: November 2026 | M11: December 2026
A12: =IF('⚙️ Parametres'!C2<>"",'⚙️ Parametres'!C2,"") -> ANALYSTES (mis a jour depuis Access) | B12: =IF(A12<>"",COUNTIFS('📋 Suspens'!E:E,A12,'📋 Suspens'!O:O,"January 2026"),"") -> 0 | C12: =IF(A12<>"",COUNTIFS('📋 Suspens'!E:E,A12,'📋 Suspens'!O:O,"February 2026"),"") -> 0 | D12: =IF(A12<>"",COUNTIFS('📋 Suspens'!E:E,A12,'📋 Suspens'!O:O,"March 2026"),"") -> 0 | E12: =IF(A12<>"",COUNTIFS('📋 Suspens'!E:E,A12,'📋 Suspens'!O:O,"April 2026"),"") -> 0 | F12: =IF(A12<>"",COUNTIFS('📋 Suspens'!E:E,A12,'📋 Suspens'!O:O,"May 2026"),"") -> 0 | G12: =IF(A12<>"",COUNTIFS('📋 Suspens'!E:E,A12,'📋 Suspens'!O:O,"June 2026"),"") -> 0 | H12: =IF(A12<>"",COUNTIFS('📋 Suspens'!E:E,A12,'📋 Suspens'!O:O,"July 2026"),"") -> 0 | I12: =IF(A12<>"",COUNTIFS('📋 Suspens'!E:E,A12,'📋 Suspens'!O:O,"August 2026"),"") -> 0 | J12: =IF(A12<>"",COUNTIFS('📋 Suspens'!E:E,A12,'📋 Suspens'!O:O,"September 2026"),"") -> 0 | K12: =IF(A12<>"",COUNTIFS('📋 Suspens'!E:E,A12,'📋 Suspens'!O:O,"October 2026"),"") -> 0 | L12: =IF(A12<>"",COUNTIFS('📋 Suspens'!E:E,A12,'📋 Suspens'!O:O,"November 2026"),"") -> 0 | M12: =IF(A12<>"",COUNTIFS('📋 Suspens'!E:E,A12,'📋 Suspens'!O:O,"December 2026"),"") -> 0
A13: =IF('⚙️ Parametres'!C3<>"",'⚙️ Parametres'!C3,"") | B13: =IF(A13<>"",COUNTIFS('📋 Suspens'!E:E,A13,'📋 Suspens'!O:O,"January 2026"),"") | C13: =IF(A13<>"",COUNTIFS('📋 Suspens'!E:E,A13,'📋 Suspens'!O:O,"February 2026"),"") | D13: =IF(A13<>"",COUNTIFS('📋 Suspens'!E:E,A13,'📋 Suspens'!O:O,"March 2026"),"") | E13: =IF(A13<>"",COUNTIFS('📋 Suspens'!E:E,A13,'📋 Suspens'!O:O,"April 2026"),"") | F13: =IF(A13<>"",COUNTIFS('📋 Suspens'!E:E,A13,'📋 Suspens'!O:O,"May 2026"),"") | G13: =IF(A13<>"",COUNTIFS('📋 Suspens'!E:E,A13,'📋 Suspens'!O:O,"June 2026"),"") | H13: =IF(A13<>"",COUNTIFS('📋 Suspens'!E:E,A13,'📋 Suspens'!O:O,"July 2026"),"") | I13: =IF(A13<>"",COUNTIFS('📋 Suspens'!E:E,A13,'📋 Suspens'!O:O,"August 2026"),"") | J13: =IF(A13<>"",COUNTIFS('📋 Suspens'!E:E,A13,'📋 Suspens'!O:O,"September 2026"),"") | K13: =IF(A13<>"",COUNTIFS('📋 Suspens'!E:E,A13,'📋 Suspens'!O:O,"October 2026"),"") | L13: =IF(A13<>"",COUNTIFS('📋 Suspens'!E:E,A13,'📋 Suspens'!O:O,"November 2026"),"") | M13: =IF(A13<>"",COUNTIFS('📋 Suspens'!E:E,A13,'📋 Suspens'!O:O,"December 2026"),"")
A14: =IF('⚙️ Parametres'!C4<>"",'⚙️ Parametres'!C4,"") | B14: =IF(A14<>"",COUNTIFS('📋 Suspens'!E:E,A14,'📋 Suspens'!O:O,"January 2026"),"") | C14: =IF(A14<>"",COUNTIFS('📋 Suspens'!E:E,A14,'📋 Suspens'!O:O,"February 2026"),"") | D14: =IF(A14<>"",COUNTIFS('📋 Suspens'!E:E,A14,'📋 Suspens'!O:O,"March 2026"),"") | E14: =IF(A14<>"",COUNTIFS('📋 Suspens'!E:E,A14,'📋 Suspens'!O:O,"April 2026"),"") | F14: =IF(A14<>"",COUNTIFS('📋 Suspens'!E:E,A14,'📋 Suspens'!O:O,"May 2026"),"") | G14: =IF(A14<>"",COUNTIFS('📋 Suspens'!E:E,A14,'📋 Suspens'!O:O,"June 2026"),"") | H14: =IF(A14<>"",COUNTIFS('📋 Suspens'!E:E,A14,'📋 Suspens'!O:O,"July 2026"),"") | I14: =IF(A14<>"",COUNTIFS('📋 Suspens'!E:E,A14,'📋 Suspens'!O:O,"August 2026"),"") | J14: =IF(A14<>"",COUNTIFS('📋 Suspens'!E:E,A14,'📋 Suspens'!O:O,"September 2026"),"") | K14: =IF(A14<>"",COUNTIFS('📋 Suspens'!E:E,A14,'📋 Suspens'!O:O,"October 2026"),"") | L14: =IF(A14<>"",COUNTIFS('📋 Suspens'!E:E,A14,'📋 Suspens'!O:O,"November 2026"),"") | M14: =IF(A14<>"",COUNTIFS('📋 Suspens'!E:E,A14,'📋 Suspens'!O:O,"December 2026"),"")
A15: =IF('⚙️ Parametres'!C5<>"",'⚙️ Parametres'!C5,"") | B15: =IF(A15<>"",COUNTIFS('📋 Suspens'!E:E,A15,'📋 Suspens'!O:O,"January 2026"),"") | C15: =IF(A15<>"",COUNTIFS('📋 Suspens'!E:E,A15,'📋 Suspens'!O:O,"February 2026"),"") | D15: =IF(A15<>"",COUNTIFS('📋 Suspens'!E:E,A15,'📋 Suspens'!O:O,"March 2026"),"") | E15: =IF(A15<>"",COUNTIFS('📋 Suspens'!E:E,A15,'📋 Suspens'!O:O,"April 2026"),"") | F15: =IF(A15<>"",COUNTIFS('📋 Suspens'!E:E,A15,'📋 Suspens'!O:O,"May 2026"),"") | G15: =IF(A15<>"",COUNTIFS('📋 Suspens'!E:E,A15,'📋 Suspens'!O:O,"June 2026"),"") | H15: =IF(A15<>"",COUNTIFS('📋 Suspens'!E:E,A15,'📋 Suspens'!O:O,"July 2026"),"") | I15: =IF(A15<>"",COUNTIFS('📋 Suspens'!E:E,A15,'📋 Suspens'!O:O,"August 2026"),"") | J15: =IF(A15<>"",COUNTIFS('📋 Suspens'!E:E,A15,'📋 Suspens'!O:O,"September 2026"),"") | K15: =IF(A15<>"",COUNTIFS('📋 Suspens'!E:E,A15,'📋 Suspens'!O:O,"October 2026"),"") | L15: =IF(A15<>"",COUNTIFS('📋 Suspens'!E:E,A15,'📋 Suspens'!O:O,"November 2026"),"") | M15: =IF(A15<>"",COUNTIFS('📋 Suspens'!E:E,A15,'📋 Suspens'!O:O,"December 2026"),"")
A16: =IF('⚙️ Parametres'!C6<>"",'⚙️ Parametres'!C6,"") | B16: =IF(A16<>"",COUNTIFS('📋 Suspens'!E:E,A16,'📋 Suspens'!O:O,"January 2026"),"") | C16: =IF(A16<>"",COUNTIFS('📋 Suspens'!E:E,A16,'📋 Suspens'!O:O,"February 2026"),"") | D16: =IF(A16<>"",COUNTIFS('📋 Suspens'!E:E,A16,'📋 Suspens'!O:O,"March 2026"),"") | E16: =IF(A16<>"",COUNTIFS('📋 Suspens'!E:E,A16,'📋 Suspens'!O:O,"April 2026"),"") | F16: =IF(A16<>"",COUNTIFS('📋 Suspens'!E:E,A16,'📋 Suspens'!O:O,"May 2026"),"") | G16: =IF(A16<>"",COUNTIFS('📋 Suspens'!E:E,A16,'📋 Suspens'!O:O,"June 2026"),"") | H16: =IF(A16<>"",COUNTIFS('📋 Suspens'!E:E,A16,'📋 Suspens'!O:O,"July 2026"),"") | I16: =IF(A16<>"",COUNTIFS('📋 Suspens'!E:E,A16,'📋 Suspens'!O:O,"August 2026"),"") | J16: =IF(A16<>"",COUNTIFS('📋 Suspens'!E:E,A16,'📋 Suspens'!O:O,"September 2026"),"") | K16: =IF(A16<>"",COUNTIFS('📋 Suspens'!E:E,A16,'📋 Suspens'!O:O,"October 2026"),"") | L16: =IF(A16<>"",COUNTIFS('📋 Suspens'!E:E,A16,'📋 Suspens'!O:O,"November 2026"),"") | M16: =IF(A16<>"",COUNTIFS('📋 Suspens'!E:E,A16,'📋 Suspens'!O:O,"December 2026"),"")
A17: =IF('⚙️ Parametres'!C7<>"",'⚙️ Parametres'!C7,"") | B17: =IF(A17<>"",COUNTIFS('📋 Suspens'!E:E,A17,'📋 Suspens'!O:O,"January 2026"),"") | C17: =IF(A17<>"",COUNTIFS('📋 Suspens'!E:E,A17,'📋 Suspens'!O:O,"February 2026"),"") | D17: =IF(A17<>"",COUNTIFS('📋 Suspens'!E:E,A17,'📋 Suspens'!O:O,"March 2026"),"") | E17: =IF(A17<>"",COUNTIFS('📋 Suspens'!E:E,A17,'📋 Suspens'!O:O,"April 2026"),"") | F17: =IF(A17<>"",COUNTIFS('📋 Suspens'!E:E,A17,'📋 Suspens'!O:O,"May 2026"),"") | G17: =IF(A17<>"",COUNTIFS('📋 Suspens'!E:E,A17,'📋 Suspens'!O:O,"June 2026"),"") | H17: =IF(A17<>"",COUNTIFS('📋 Suspens'!E:E,A17,'📋 Suspens'!O:O,"July 2026"),"") | I17: =IF(A17<>"",COUNTIFS('📋 Suspens'!E:E,A17,'📋 Suspens'!O:O,"August 2026"),"") | J17: =IF(A17<>"",COUNTIFS('📋 Suspens'!E:E,A17,'📋 Suspens'!O:O,"September 2026"),"") | K17: =IF(A17<>"",COUNTIFS('📋 Suspens'!E:E,A17,'📋 Suspens'!O:O,"October 2026"),"") | L17: =IF(A17<>"",COUNTIFS('📋 Suspens'!E:E,A17,'📋 Suspens'!O:O,"November 2026"),"") | M17: =IF(A17<>"",COUNTIFS('📋 Suspens'!E:E,A17,'📋 Suspens'!O:O,"December 2026"),"")
A18: =IF('⚙️ Parametres'!C8<>"",'⚙️ Parametres'!C8,"") | B18: =IF(A18<>"",COUNTIFS('📋 Suspens'!E:E,A18,'📋 Suspens'!O:O,"January 2026"),"") | C18: =IF(A18<>"",COUNTIFS('📋 Suspens'!E:E,A18,'📋 Suspens'!O:O,"February 2026"),"") | D18: =IF(A18<>"",COUNTIFS('📋 Suspens'!E:E,A18,'📋 Suspens'!O:O,"March 2026"),"") | E18: =IF(A18<>"",COUNTIFS('📋 Suspens'!E:E,A18,'📋 Suspens'!O:O,"April 2026"),"") | F18: =IF(A18<>"",COUNTIFS('📋 Suspens'!E:E,A18,'📋 Suspens'!O:O,"May 2026"),"") | G18: =IF(A18<>"",COUNTIFS('📋 Suspens'!E:E,A18,'📋 Suspens'!O:O,"June 2026"),"") | H18: =IF(A18<>"",COUNTIFS('📋 Suspens'!E:E,A18,'📋 Suspens'!O:O,"July 2026"),"") | I18: =IF(A18<>"",COUNTIFS('📋 Suspens'!E:E,A18,'📋 Suspens'!O:O,"August 2026"),"") | J18: =IF(A18<>"",COUNTIFS('📋 Suspens'!E:E,A18,'📋 Suspens'!O:O,"September 2026"),"") | K18: =IF(A18<>"",COUNTIFS('📋 Suspens'!E:E,A18,'📋 Suspens'!O:O,"October 2026"),"") | L18: =IF(A18<>"",COUNTIFS('📋 Suspens'!E:E,A18,'📋 Suspens'!O:O,"November 2026"),"") | M18: =IF(A18<>"",COUNTIFS('📋 Suspens'!E:E,A18,'📋 Suspens'!O:O,"December 2026"),"")
A19: =IF('⚙️ Parametres'!C9<>"",'⚙️ Parametres'!C9,"") | B19: =IF(A19<>"",COUNTIFS('📋 Suspens'!E:E,A19,'📋 Suspens'!O:O,"January 2026"),"") | C19: =IF(A19<>"",COUNTIFS('📋 Suspens'!E:E,A19,'📋 Suspens'!O:O,"February 2026"),"") | D19: =IF(A19<>"",COUNTIFS('📋 Suspens'!E:E,A19,'📋 Suspens'!O:O,"March 2026"),"") | E19: =IF(A19<>"",COUNTIFS('📋 Suspens'!E:E,A19,'📋 Suspens'!O:O,"April 2026"),"") | F19: =IF(A19<>"",COUNTIFS('📋 Suspens'!E:E,A19,'📋 Suspens'!O:O,"May 2026"),"") | G19: =IF(A19<>"",COUNTIFS('📋 Suspens'!E:E,A19,'📋 Suspens'!O:O,"June 2026"),"") | H19: =IF(A19<>"",COUNTIFS('📋 Suspens'!E:E,A19,'📋 Suspens'!O:O,"July 2026"),"") | I19: =IF(A19<>"",COUNTIFS('📋 Suspens'!E:E,A19,'📋 Suspens'!O:O,"August 2026"),"") | J19: =IF(A19<>"",COUNTIFS('📋 Suspens'!E:E,A19,'📋 Suspens'!O:O,"September 2026"),"") | K19: =IF(A19<>"",COUNTIFS('📋 Suspens'!E:E,A19,'📋 Suspens'!O:O,"October 2026"),"") | L19: =IF(A19<>"",COUNTIFS('📋 Suspens'!E:E,A19,'📋 Suspens'!O:O,"November 2026"),"") | M19: =IF(A19<>"",COUNTIFS('📋 Suspens'!E:E,A19,'📋 Suspens'!O:O,"December 2026"),"")
A20: =IF('⚙️ Parametres'!C10<>"",'⚙️ Parametres'!C10,"") | B20: =IF(A20<>"",COUNTIFS('📋 Suspens'!E:E,A20,'📋 Suspens'!O:O,"January 2026"),"") | C20: =IF(A20<>"",COUNTIFS('📋 Suspens'!E:E,A20,'📋 Suspens'!O:O,"February 2026"),"") | D20: =IF(A20<>"",COUNTIFS('📋 Suspens'!E:E,A20,'📋 Suspens'!O:O,"March 2026"),"") | E20: =IF(A20<>"",COUNTIFS('📋 Suspens'!E:E,A20,'📋 Suspens'!O:O,"April 2026"),"") | F20: =IF(A20<>"",COUNTIFS('📋 Suspens'!E:E,A20,'📋 Suspens'!O:O,"May 2026"),"") | G20: =IF(A20<>"",COUNTIFS('📋 Suspens'!E:E,A20,'📋 Suspens'!O:O,"June 2026"),"") | H20: =IF(A20<>"",COUNTIFS('📋 Suspens'!E:E,A20,'📋 Suspens'!O:O,"July 2026"),"") | I20: =IF(A20<>"",COUNTIFS('📋 Suspens'!E:E,A20,'📋 Suspens'!O:O,"August 2026"),"") | J20: =IF(A20<>"",COUNTIFS('📋 Suspens'!E:E,A20,'📋 Suspens'!O:O,"September 2026"),"") | K20: =IF(A20<>"",COUNTIFS('📋 Suspens'!E:E,A20,'📋 Suspens'!O:O,"October 2026"),"") | L20: =IF(A20<>"",COUNTIFS('📋 Suspens'!E:E,A20,'📋 Suspens'!O:O,"November 2026"),"") | M20: =IF(A20<>"",COUNTIFS('📋 Suspens'!E:E,A20,'📋 Suspens'!O:O,"December 2026"),"")
A21: =IF('⚙️ Parametres'!C11<>"",'⚙️ Parametres'!C11,"") | B21: =IF(A21<>"",COUNTIFS('📋 Suspens'!E:E,A21,'📋 Suspens'!O:O,"January 2026"),"") | C21: =IF(A21<>"",COUNTIFS('📋 Suspens'!E:E,A21,'📋 Suspens'!O:O,"February 2026"),"") | D21: =IF(A21<>"",COUNTIFS('📋 Suspens'!E:E,A21,'📋 Suspens'!O:O,"March 2026"),"") | E21: =IF(A21<>"",COUNTIFS('📋 Suspens'!E:E,A21,'📋 Suspens'!O:O,"April 2026"),"") | F21: =IF(A21<>"",COUNTIFS('📋 Suspens'!E:E,A21,'📋 Suspens'!O:O,"May 2026"),"") | G21: =IF(A21<>"",COUNTIFS('📋 Suspens'!E:E,A21,'📋 Suspens'!O:O,"June 2026"),"") | H21: =IF(A21<>"",COUNTIFS('📋 Suspens'!E:E,A21,'📋 Suspens'!O:O,"July 2026"),"") | I21: =IF(A21<>"",COUNTIFS('📋 Suspens'!E:E,A21,'📋 Suspens'!O:O,"August 2026"),"") | J21: =IF(A21<>"",COUNTIFS('📋 Suspens'!E:E,A21,'📋 Suspens'!O:O,"September 2026"),"") | K21: =IF(A21<>"",COUNTIFS('📋 Suspens'!E:E,A21,'📋 Suspens'!O:O,"October 2026"),"") | L21: =IF(A21<>"",COUNTIFS('📋 Suspens'!E:E,A21,'📋 Suspens'!O:O,"November 2026"),"") | M21: =IF(A21<>"",COUNTIFS('📋 Suspens'!E:E,A21,'📋 Suspens'!O:O,"December 2026"),"")
A22: =IF('⚙️ Parametres'!C12<>"",'⚙️ Parametres'!C12,"") | B22: =IF(A22<>"",COUNTIFS('📋 Suspens'!E:E,A22,'📋 Suspens'!O:O,"January 2026"),"") | C22: =IF(A22<>"",COUNTIFS('📋 Suspens'!E:E,A22,'📋 Suspens'!O:O,"February 2026"),"") | D22: =IF(A22<>"",COUNTIFS('📋 Suspens'!E:E,A22,'📋 Suspens'!O:O,"March 2026"),"") | E22: =IF(A22<>"",COUNTIFS('📋 Suspens'!E:E,A22,'📋 Suspens'!O:O,"April 2026"),"") | F22: =IF(A22<>"",COUNTIFS('📋 Suspens'!E:E,A22,'📋 Suspens'!O:O,"May 2026"),"") | G22: =IF(A22<>"",COUNTIFS('📋 Suspens'!E:E,A22,'📋 Suspens'!O:O,"June 2026"),"") | H22: =IF(A22<>"",COUNTIFS('📋 Suspens'!E:E,A22,'📋 Suspens'!O:O,"July 2026"),"") | I22: =IF(A22<>"",COUNTIFS('📋 Suspens'!E:E,A22,'📋 Suspens'!O:O,"August 2026"),"") | J22: =IF(A22<>"",COUNTIFS('📋 Suspens'!E:E,A22,'📋 Suspens'!O:O,"September 2026"),"") | K22: =IF(A22<>"",COUNTIFS('📋 Suspens'!E:E,A22,'📋 Suspens'!O:O,"October 2026"),"") | L22: =IF(A22<>"",COUNTIFS('📋 Suspens'!E:E,A22,'📋 Suspens'!O:O,"November 2026"),"") | M22: =IF(A22<>"",COUNTIFS('📋 Suspens'!E:E,A22,'📋 Suspens'!O:O,"December 2026"),"")
A23: =IF('⚙️ Parametres'!C13<>"",'⚙️ Parametres'!C13,"") | B23: =IF(A23<>"",COUNTIFS('📋 Suspens'!E:E,A23,'📋 Suspens'!O:O,"January 2026"),"") | C23: =IF(A23<>"",COUNTIFS('📋 Suspens'!E:E,A23,'📋 Suspens'!O:O,"February 2026"),"") | D23: =IF(A23<>"",COUNTIFS('📋 Suspens'!E:E,A23,'📋 Suspens'!O:O,"March 2026"),"") | E23: =IF(A23<>"",COUNTIFS('📋 Suspens'!E:E,A23,'📋 Suspens'!O:O,"April 2026"),"") | F23: =IF(A23<>"",COUNTIFS('📋 Suspens'!E:E,A23,'📋 Suspens'!O:O,"May 2026"),"") | G23: =IF(A23<>"",COUNTIFS('📋 Suspens'!E:E,A23,'📋 Suspens'!O:O,"June 2026"),"") | H23: =IF(A23<>"",COUNTIFS('📋 Suspens'!E:E,A23,'📋 Suspens'!O:O,"July 2026"),"") | I23: =IF(A23<>"",COUNTIFS('📋 Suspens'!E:E,A23,'📋 Suspens'!O:O,"August 2026"),"") | J23: =IF(A23<>"",COUNTIFS('📋 Suspens'!E:E,A23,'📋 Suspens'!O:O,"September 2026"),"") | K23: =IF(A23<>"",COUNTIFS('📋 Suspens'!E:E,A23,'📋 Suspens'!O:O,"October 2026"),"") | L23: =IF(A23<>"",COUNTIFS('📋 Suspens'!E:E,A23,'📋 Suspens'!O:O,"November 2026"),"") | M23: =IF(A23<>"",COUNTIFS('📋 Suspens'!E:E,A23,'📋 Suspens'!O:O,"December 2026"),"")
... A61: =IF('⚙️ Parametres'!C51<>"",'⚙️ Parametres'!C51,"") | B61: =IF(A61<>"",COUNTIFS('📋 Suspens'!E:E,A61,'📋 Suspens'!O:O,"January 2026"),"") | C61: =IF(A61<>"",COUNTIFS('📋 Suspens'!E:E,A61,'📋 Suspens'!O:O,"February 2026"),"") | D61: =IF(A61<>"",COUNTIFS('📋 Suspens'!E:E,A61,'📋 Suspens'!O:O,"March 2026"),"") | E61: =IF(A61<>"",COUNTIFS('📋 Suspens'!E:E,A61,'📋 Suspens'!O:O,"April 2026"),"") | F61: =IF(A61<>"",COUNTIFS('📋 Suspens'!E:E,A61,'📋 Suspens'!O:O,"May 2026"),"") | G61: =IF(A61<>"",COUNTIFS('📋 Suspens'!E:E,A61,'📋 Suspens'!O:O,"June 2026"),"") | H61: =IF(A61<>"",COUNTIFS('📋 Suspens'!E:E,A61,'📋 Suspens'!O:O,"July 2026"),"") | I61: =IF(A61<>"",COUNTIFS('📋 Suspens'!E:E,A61,'📋 Suspens'!O:O,"August 2026"),"") | J61: =IF(A61<>"",COUNTIFS('📋 Suspens'!E:E,A61,'📋 Suspens'!O:O,"September 2026"),"") | K61: =IF(A61<>"",COUNTIFS('📋 Suspens'!E:E,A61,'📋 Suspens'!O:O,"October 2026"),"") | L61: =IF(A61<>"",COUNTIFS('📋 Suspens'!E:E,A61,'📋 Suspens'!O:O,"November 2026"),"") | M61: =IF(A61<>"",COUNTIFS('📋 Suspens'!E:E,A61,'📋 Suspens'!O:O,"December 2026"),"")

Sheet ⚙️ Parametres
A1: PARAMETRES | SGCI
A2: RAISONS DE SUSPENS (modifiables) | C2: ANALYSTES (mis a jour depuis Access) | E2: CHEMIN ACCESS
A3: Absence de CREDAPP | E3: =CONFIG!B1 -> S:\DRR_NOTIFICATION_DE_CREDIT\DEAL FLOW\OUTIL_DEAL_FLOW.accbd
A4: Absence de notice financiere | E4: Pour modifier : aller dans CONFIG > cellule B1
A5: Absence de page de signature
A6: Absence de rapport CAC ou derogation CRO
A7: Absence de fiche KYC
A8: Absence des fiches RBO
A9: Absence de la fiche CLEO
A10: Absence de la GL du PCRU
A11: Absence de projet de note NOVA
A12: Absence de la fiche RSE
A13: Absence de quitus fiscal
A14: Absence de fiche BIC
A15: Absence de mail de formalisation de garanties
A16: Absence de chiffres intermediaires
... A29: Autre
C31: -> Mis a jour automatiquement a chaque actualisation Access

Sheet 📌 VBA Setup
A1: INSTALLATION VBA | A FAIRE UNE SEULE FOIS
A3: 1 | B3: Sauvegarder ce fichier en .xlsm : Fichier > Enregistrer sous > Excel avec macros (.xlsm)
A4: 2 | B4: Ouvrir l'editeur VBA : Alt + F11
A5: 3 | B5: Dans le menu : Insertion > Module (un nouveau module vide s'ouvre)
A6: 4 | B6: Selectionner TOUT le code ci-dessous (a partir de 'Option Explicit') et le coller dans le module
A7: 5 | B7: Fermer l'editeur VBA (Alt+F4)
A8: 6 | B8: Dans la feuille Accueil : faire un clic droit sur la cellule verte 'ACTUALISER' > Affecter une macro > ActualiserDepuisAccess
A9: 7 | B9: Aller dans CONFIG (feuille cachee) ou Parametres > modifier le chemin Access en cellule B1 / E3
A10: 8 | B10: Cliquer sur ACTUALISER pour tester la connexion
A13: CODE VBA A COPIER INTEGRALEMENT DANS LE MODULE (commencer a 'Option Explicit')
A14: 1 | B14: Option Explicit
A15: 2
A16: 3 | B16: ' ================================================================
A17: 4 | B17: ' SUIVI DES SUSPENS - SGCI
A18: 5 | B18: ' Connexion automatique a la base Access via ADODB
A19: 6 | B19: ' Feuilles referencees par index pour eviter les problemes d encodage
A20: 7 | B20: ' Index 1 = CONFIG
A21: 8 | B21: ' Index 2 = Accueil
A22: 9 | B22: ' Index 3 = Donnees Access
A23: 10 | B23: ' Index 4 = Suspens
A24: 11 | B24: ' Index 5 = Statistiques
A25: 12 | B25: ' Index 6 = Graphiques
A26: 13 | B26: ' Index 7 = Mensuel
A27: 14 | B27: ' Index 8 = Parametres
... A29: 16 | B29: ' ================================================================
A30: 17
A31: 18 | B31: Sub ActualiserDepuisAccess()
A32: 19
A33: 20 | B33: Dim sPath As String
A34: 21 | B34: Dim conn As Object
A35: 22 | B35: Dim rs As Object
A36: 23 | B36: Dim rsAn As Object
A37: 24 | B37: Dim wsDat As Worksheet
A38: 25 | B38: Dim wsSus As Worksheet
A39: 26 | B39: Dim wsCfg As Worksheet
A40: 27 | B40: Dim wsPrm As Worksheet
A41: 28 | B41: Dim i As Long
A42: 29 | B42: Dim lastRow As Long
A43: 30
A44: 31 | B44: Application.ScreenUpdating = False
...
